Workbook

Sheet Resumen
B2: RESUMEN EJECUTIVO
B3: Se recalcula solo al cambiar la hoja Datos.
B5: PORTAFOLIO
B6: Repuestos con datos | C6: =COUNT(Datos!D2:D301)
B7: Clase A (paran la planta) | C7: =COUNTIF(Criticidad!$AJ$2:$AJ$301,"A")
B8: Clase B | C8: =COUNTIF(Criticidad!$AJ$2:$AJ$301,"B")
B9: Clase C | C9: =COUNTIF(Criticidad!$AJ$2:$AJ$301,"C")
B11: CAPITAL
B12: Capital inmovilizado hoy | C12: =SUMPRODUCT(Criticidad!$C$2:$C$301,N(Criticidad!$AQ$2:$AQ$301))
B13: Capital liberable (sobrestock) | C13: =SUM(Criticidad!$AS$2:$AS$301)
B14: % del capital que sobra | C14: =IF(C12=0,0,C13/C12)
B16: RIESGO
B17: Repuestos bajo cobertura | C17: =COUNTIF(Criticidad!$AT$2:$AT$301,"SI")
B18: de ellos clase A | C18: =COUNTIFS(Criticidad!$AT$2:$AT$301,"SI",Criticidad!$AJ$2:$AJ$301,"A")
B19: Repuestos a reponer ahora | C19: =COUNTIF(Criticidad!$AU$2:$AU$301,"Reponer ahora")
B21: PESO OBJETIVO DE CADA CRITERIO (entropia de Shannon)
B22: =Criticidad!BA2 | C22: =Criticidad!BE2
B23: =Criticidad!BA3 | C23: =Criticidad!BE3
B24: =Criticidad!BA4 | C24: =Criticidad!BE4
B25: =Criticidad!BA5 | C25: =Criticidad!BE5
B26: =Criticidad!BA6 | C26: =Criticidad!BE6
B27: =Criticidad!BA7 | C27: =Criticidad!BE7

Sheet Instrucciones
B2: KIT DE CRITICIDAD DE REPUESTOS
B3: Clasificacion multicriterio y politica de inventario (R,S) en una sola planilla.
B5: COMO SE USA
B6: 1. Ve a la hoja «Datos» y reemplaza las filas de ejemplo por tu maestro de repuestos.
B7: 2. Completa al menos: SKU, precio unitario, consumo anual y lead time en dias.
B8: 3. Listo. Las hojas «Criticidad» y «Resumen» se recalculan solas.
B9: 4. En «Parametros» puedes ajustar el nivel de servicio y el periodo de revision de cada clase.
B11: QUE CALCULA
B12: Pesos por entropia de Shannon: el peso de cada criterio sale de la informacion que aporta
B13: tu propia data, no de una opinion. Un criterio que no discrimina entre repuestos, no pesa.
B15: Indice de criticidad TOPSIS: cada repuesto recibe un valor entre 0 y 1 segun su distancia
B16: a la solucion ideal y a la anti-ideal. Es comparable entre plantas y a lo largo del tiempo.
... B32: fila de «Criticidad» hacia abajo y extiende los rangos, o usa la version web sin limite.

Sheet Datos
A1: SKU | B1: Descripcion | C1: Categoria | D1: Precio unitario | E1: Consumo anual | F1: Lead time (dias) | G1: Criticidad equipo (1-5) | H1: Horas parada si falla | I1: N proveedores | J1: Stock actual
A2: SP-1000 | B2: Rodamiento rigido de bolas 6210 | C2: Rodamientos | D2: 60.3 | E2: 77 | F2: 8 | G2: 4 | H2: 29 | I2: 3 | J2: 16
A3: SP-1001 | B3: Rodamiento a rodillos conicos 32216 | C3: Rodamientos | D3: 274.24 | E3: 14 | F3: 26 | G3: 3 | H3: 29 | I3: 1 | J3: 0
A4: SP-1002 | B4: Sello mecanico bomba centrifuga 3x2 | C4: Sellos | D4: 392.53 | E4: 40 | F4: 38 | G4: 5 | H4: 22 | I4: 1 | J4: 0
A5: SP-1003 | B5: Sello mecanico cartucho API 682 | C5: Sellos | D5: 1523.87 | E5: 16 | F5: 65 | G5: 5 | H5: 14 | I5: 1 | J5: 9
A6: SP-1004 | B6: Correa en V C-120 | C6: Transmision | D6: 47.27 | E6: 109 | F6: 13 | G6: 2 | H6: 21 | I6: 4 | J6: 0
A7: SP-1005 | B7: Correa dentada HTD 8M-1600 | C7: Transmision | D7: 150.84 | E7: 52 | F7: 17 | G7: 3 | H7: 17 | I7: 1 | J7: 20
A8: SP-1006 | B8: Filtro hidraulico 10 micrones | C8: Filtracion | D8: 78.28 | E8: 41 | F8: 17 | G8: 3 | H8: 10 | I8: 4 | J8: 6
A9: SP-1007 | B9: Cartucho filtrante 5 um 40" | C9: Filtracion | D9: 23.86 | E9: 31 | F9: 21 | G9: 3 | H9: 27 | I9: 5 | J9: 20
A10: SP-1008 | B10: Membrana osmosis inversa 8040 | C10: Tratamiento | D10: 832.45 | E10: 17 | F10: 93 | G10: 5 | H10: 42 | I10: 1 | J10: 11
A11: SP-1009 | B11: Resina cationica fuerte (saco 25L) | C11: Tratamiento | D11: 364.37 | E11: 26 | F11: 66 | G11: 4 | H11: 41 | I11: 2 | J11: 3
A12: SP-1010 | B12: Valvula mariposa DN150 wafer | C12: Valvulas | D12: 690.89 | E12: 30 | F12: 44 | G12: 4 | H12: 30 | I12: 3 | J12: 15
A13: SP-1011 | B13: Valvula de bola inox 2" 3 piezas | C13: Valvulas | D13: 251.71 | E13: 18 | F13: 24 | G13: 3 | H13: 6 | I13: 4 | J13: 3
... A61: SP-1059 | B61: Rele termico 30-40 A (var. 2) | C61: Electrico | D61: 79.88 | E61: 14 | F61: 13 | G61: 3 | H61: 25 | I61: 3 | J61: 3

Sheet Criticidad
A1: SKU | B1: Descripcion | C1: Precio | D1: Consumo | E1: Lead time | F1: Crit. equipo | G1: Horas parada | H1: N prov. | J1: mm Precio | K1: mm Consumo | L1: mm Lead | M1: mm Crit | N1: mm Horas | O1: mm Prov | Q1: pln Precio | R1: pln Consumo | S1: pln Lead | T1: pln Crit | U1: pln Horas | V1: pln Prov | X1: v Precio | Y1: v Consumo | Z1: v Lead | AA1: v Crit | AB1: v Horas | AC1: v Prov | AE1: D+ | AF1: D- | AG1: Indice criticidad | AH1: Impacto | AI1: % acumulado | AJ1: Clase | AK1: Servicio | AL1: Revision (d) | AM1: z | AN1: Demanda diaria | AO1: Stock seguridad | AP1: Nivel objetivo S | AQ1: Stock actual | AR1: Exceso (un) | AS1: Capital liberable | AT1: Riesgo | AU1: Accion | BA1: Criterio | BB1: Sentido | BC1: Entropia e | BD1: Divergencia | BE1: Peso
A2: =IF(Datos!A2="","",Datos!A2) | B2: =IF(Datos!A2="","",Datos!B2) | C2: =IF(Datos!A2="","",IFERROR(MAX(0,N(Datos!D2)),0)) | D2: =IF(Datos!A2="","",IFERROR(MAX(0,N(Datos!E2)),0)) | E2: =IF(Datos!A2="","",IFERROR(MAX(0,N(Datos!F2)),0)) | F2: =IF(Datos!A2="","",IFERROR(MAX(0,N(Datos!G2)),0)) | G2: =IF(Datos!A2="","",IFERROR(MAX(0,N(Datos!H2)),0)) | H2: =IF(Datos!A2="","",IFERROR(MAX(0,N(Datos!I2)),0)) | J2: =IF(Datos!A2="","",IF(MAX(C$2:C$301)-MIN(C$2:C$301)<0.000000001,0.5,(C2-MIN(C$2:C$301))/(MAX(C$2:C$301)-MIN(C$2:C$301)))+0.000000001) | K2: =IF(Datos!A2="","",IF(MAX(D$2:D$301)-MIN(D$2:D$301)<0.000000001,0.5,(D2-MIN(D$2:D$301))/(MAX(D$2:D$301)-MIN(D$2:D$301)))+0.000000001) | L2: =IF(Datos!A2="","",IF(MAX(E$2:E$301)-MIN(E$2:E$301)<0.000000001,0.5,(E2-MIN(E$2:E$301))/(MAX(E$2:E$301)-MIN(E$2:E$301)))+0.000000001) | M2: =IF(Datos!A2="","",IF(MAX(F$2:F$301)-MIN(F$2:F$301)<0.000000001,0.5,(F2-MIN(F$2:F$301))/(MAX(F$2:F$301)-MIN(F$2:F$301)))+0.000000001) | N2: =IF(Datos!A2="","",IF(MAX(G$2:G$301)-MIN(G$2:G$301)<0.000000001,0.5,(G2-MIN(G$2:G$301))/(MAX(G$2:G$301)-MIN(G$2:G$301)))+0.000000001) | O2: =IF(Datos!A2="","",IF(MAX(H$2:H$301)-MIN(H$2:H$301)<0.000000001,0.5,(H2-MIN(H$2:H$301))/(MAX(H$2:H$301)-MIN(H$2:H$301)))+0.000000001) | Q2: =IF(Datos!A2="","",(J2/SUM(J$2:J$301))*LN(J2/SUM(J$2:J$301))) | R2: =IF(Datos!A2="","",(K2/SUM(K$2:K$301))*LN(K2/SUM(K$2:K$301))) | S2: =IF(Datos!A2="","",(L2/SUM(L$2:L$301))*LN(L2/SUM(L$2:L$301))) | T2: =IF(Datos!A2="","",(M2/SUM(M$2:M$301))*LN(M2/SUM(M$2:M$301))) | U2: =IF(Datos!A2="","",(N2/SUM(N$2:N$301))*LN(N2/SUM(N$2:N$301))) | V2: =IF(Datos!A2="","",(O2/SUM(O$2:O$301))*LN(O2/SUM(O$2:O$301))) | X2: =IF(Datos!A2="","",IF(SUMSQ(C$2:C$301)=0,0,C2/SQRT(SUMSQ(C$2:C$301)))*$BE$2) | Y2: =IF(Datos!A2="","",IF(SUMSQ(D$2:D$301)=0,0,D2/SQRT(SUMSQ(D$2:D$301)))*$BE$3) | Z2: =IF(Datos!A2="","",IF(SUMSQ(E$2:E$301)=0,0,E2/SQRT(SUMSQ(E$2:E$301)))*$BE$4) | AA2: =IF(Datos!A2="","",IF(SUMSQ(F$2:F$301)=0,0,F2/SQRT(SUMSQ(F$2:F$301)))*$BE$5) | AB2: =IF(Datos!A2="","",IF(SUMSQ(G$2:G$301)=0,0,G2/SQRT(SUMSQ(G$2:G$301)))*$BE$6) | AC2: =IF(Datos!A2="","",IF(SUMSQ(H$2:H$301)=0,0,H2/SQRT(SUMSQ(H$2:H$301)))*$BE$7) | AE2: =IF(Datos!A2="","",SQRT(SUMXMY2(X2:AC2,$X$303:$AC$303))) | AF2: =IF(Datos!A2="","",SQRT(SUMXMY2(X2:AC2,$X$304:$AC$304))) | AG2: =IF(Datos!A2="","",IF(AE2+AF2<0.000000001,0.5,AF2/(AE2+AF2))) | AH2: =IF(Datos!A2="","",AG2*MAX(C2*D2,1)) | AI2: =IF(Datos!A2="","",SUMIF($AH$2:$AH$301,">="&AH2,$AH$2:$AH$301)/SUM($AH$2:$AH$301)) | AJ2: =IF(Datos!A2="","",IF(AI2<=Parametros!$B$13,"A",IF(AI2<=Parametros!$B$14,"B","C"))) | AK2: =IF(Datos!A2="","",VLOOKUP(AJ2,Parametros!$A$8:$C$10,2,FALSE)) | AL2: =IF(Datos!A2="","",VLOOKUP(AJ2,Parametros!$A$8:$C$10,3,FALSE)) | AM2: =IF(Datos!A2="","",NORMSINV(AK2)) | AN2: =IF(Datos!A2="","",D2/Parametros!$B$4) | AO2: =IF(Datos!A2="","",MAX(0,ROUNDUP(AM2*(AN2*Parametros!$B$3)*SQRT((AL2+E2)),0))) | AP2: =IF(Datos!A2="","",MAX(1,ROUNDUP(AN2*(AL2+E2)+AM2*(AN2*Parametros!$B$3)*SQRT((AL2+E2)),0))) | AQ2: =IF(Datos!A2="","",IF(Datos!J2="","",Datos!J2)) | AR2: =IF(OR(Datos!A2="",AQ2=""),"",MAX(0,AQ2-AP2)) | AS2: =IF(OR(Datos!A2="",AQ2=""),"",AR2*C2) | AT2: =IF(OR(Datos!A2="",AQ2=""),"",IF(AQ2<AO2,"SI","")) | AU2: =IF(Datos!A2="","",IF(AT2="SI","Reponer ahora",IF(AND(AQ2<>"",AR2>0),"Bajar "&TEXT(AR2,"#,##0")&" un.","En rango"))) | BA2: Precio unitario | BB2: beneficio | BC2: =IF($BE$10<2,1,-1/LN($BE$10)*SUM(Q$2:Q$301)) | BD2: =MAX(0,1-BC2) | BE2: =IF(SUM($BD$2:$BD$7)<0.000000001,1/6,BD2/SUM($BD$2:$BD$7))
A3: =IF(Datos!A3="","",Datos!A3) | B3: =IF(Datos!A3="","",Datos!B3) | C3: =IF(Datos!A3="","",IFERROR(MAX(0,N(Datos!D3)),0)) | D3: =IF(Datos!A3="","",IFERROR(MAX(0,N(Datos!E3)),0)) | E3: =IF(Datos!A3="","",IFERROR(MAX(0,N(Datos!F3)),0)) | F3: =IF(Datos!A3="","",IFERROR(MAX(0,N(Datos!G3)),0)) | G3: =IF(Datos!A3="","",IFERROR(MAX(0,N(Datos!H3)),0)) | H3: =IF(Datos!A3="","",IFERROR(MAX(0,N(Datos!I3)),0)) | J3: =IF(Datos!A3="","",IF(MAX(C$2:C$301)-MIN(C$2:C$301)<0.000000001,0.5,(C3-MIN(C$2:C$301))/(MAX(C$2:C$301)-MIN(C$2:C$301)))+0.000000001) | K3: =IF(Datos!A3="","",IF(MAX(D$2:D$301)-MIN(D$2:D$301)<0.000000001,0.5,(D3-MIN(D$2:D$301))/(MAX(D$2:D$301)-MIN(D$2:D$301)))+0.000000001) | L3: =IF(Datos!A3="","",IF(MAX(E$2:E$301)-MIN(E$2:E$301)<0.000000001,0.5,(E3-MIN(E$2:E$301))/(MAX(E$2:E$301)-MIN(E$2:E$301)))+0.000000001) | M3: =IF(Datos!A3="","",IF(MAX(F$2:F$301)-MIN(F$2:F$301)<0.000000001,0.5,(F3-MIN(F$2:F$301))/(MAX(F$2:F$301)-MIN(F$2:F$301)))+0.000000001) | N3: =IF(Datos!A3="","",IF(MAX(G$2:G$301)-MIN(G$2:G$301)<0.000000001,0.5,(G3-MIN(G$2:G$301))/(MAX(G$2:G$301)-MIN(G$2:G$301)))+0.000000001) | O3: =IF(Datos!A3="","",IF(MAX(H$2:H$301)-MIN(H$2:H$301)<0.000000001,0.5,(H3-MIN(H$2:H$301))/(MAX(H$2:H$301)-MIN(H$2:H$301)))+0.000000001) | Q3: =IF(Datos!A3="","",(J3/SUM(J$2:J$301))*LN(J3/SUM(J$2:J$301))) | R3: =IF(Datos!A3="","",(K3/SUM(K$2:K$301))*LN(K3/SUM(K$2:K$301))) | S3: =IF(Datos!A3="","",(L3/SUM(L$2:L$301))*LN(L3/SUM(L$2:L$301))) | T3: =IF(Datos!A3="","",(M3/SUM(M$2:M$301))*LN(M3/SUM(M$2:M$301))) | U3: =IF(Datos!A3="","",(N3/SUM(N$2:N$301))*LN(N3/SUM(N$2:N$301))) | V3: =IF(Datos!A3="","",(O3/SUM(O$2:O$301))*LN(O3/SUM(O$2:O$301))) | X3: =IF(Datos!A3="","",IF(SUMSQ(C$2:C$301)=0,0,C3/SQRT(SUMSQ(C$2:C$301)))*$BE$2) | Y3: =IF(Datos!A3="","",IF(SUMSQ(D$2:D$301)=0,0,D3/SQRT(SUMSQ(D$2:D$301)))*$BE$3) | Z3: =IF(Datos!A3="","",IF(SUMSQ(E$2:E$301)=0,0,E3/SQRT(SUMSQ(E$2:E$301)))*$BE$4) | AA3: =IF(Datos!A3="","",IF(SUMSQ(F$2:F$301)=0,0,F3/SQRT(SUMSQ(F$2:F$301)))*$BE$5) | AB3: =IF(Datos!A3="","",IF(SUMSQ(G$2:G$301)=0,0,G3/SQRT(SUMSQ(G$2:G$301)))*$BE$6) | AC3: =IF(Datos!A3="","",IF(SUMSQ(H$2:H$301)=0,0,H3/SQRT(SUMSQ(H$2:H$301)))*$BE$7) | AE3: =IF(Datos!A3="","",SQRT(SUMXMY2(X3:AC3,$X$303:$AC$303))) | AF3: =IF(Datos!A3="","",SQRT(SUMXMY2(X3:AC3,$X$304:$AC$304))) | AG3: =IF(Datos!A3="","",IF(AE3+AF3<0.000000001,0.5,AF3/(AE3+AF3))) | AH3: =IF(Datos!A3="","",AG3*MAX(C3*D3,1)) | AI3: =IF(Datos!A3="","",SUMIF($AH$2:$AH$301,">="&AH3,$AH$2:$AH$301)/SUM($AH$2:$AH$301)) | AJ3: =IF(Datos!A3="","",IF(AI3<=Parametros!$B$13,"A",IF(AI3<=Parametros!$B$14,"B","C"))) | AK3: =IF(Datos!A3="","",VLOOKUP(AJ3,Parametros!$A$8:$C$10,2,FALSE)) | AL3: =IF(Datos!A3="","",VLOOKUP(AJ3,Parametros!$A$8:$C$10,3,FALSE)) | AM3: =IF(Datos!A3="","",NORMSINV(AK3)) | AN3: =IF(Datos!A3="","",D3/Parametros!$B$4) | AO3: =IF(Datos!A3="","",MAX(0,ROUNDUP(AM3*(AN3*Parametros!$B$3)*SQRT((AL3+E3)),0))) | AP3: =IF(Datos!A3="","",MAX(1,ROUNDUP(AN3*(AL3+E3)+AM3*(AN3*Parametros!$B$3)*SQRT((AL3+E3)),0))) | AQ3: =IF(Datos!A3="","",IF(Datos!J3="","",Datos!J3)) | AR3: =IF(OR(Datos!A3="",AQ3=""),"",MAX(0,AQ3-AP3)) | AS3: =IF(OR(Datos!A3="",AQ3=""),"",AR3*C3) | AT3: =IF(OR(Datos!A3="",AQ3=""),"",IF(AQ3<AO3,"SI","")) | AU3: =IF(Datos!A3="","",IF(AT3="SI","Reponer ahora",IF(AND(AQ3<>"",AR3>0),"Bajar "&TEXT(AR3,"#,##0")&" un.","En rango"))) | BA3: Consumo anual | BB3: beneficio | BC3: =IF($BE$10<2,1,-1/LN($BE$10)*SUM(R$2:R$301)) | BD3: =MAX(0,1-BC3) | BE3: =IF(SUM($BD$2:$BD$7)<0.000000001,1/6,BD3/SUM($BD$2:$BD$7))
A4: =IF(Datos!A4="","",Datos!A4) | B4: =IF(Datos!A4="","",Datos!B4) | C4: =IF(Datos!A4="","",IFERROR(MAX(0,N(Datos!D4)),0)) | D4: =IF(Datos!A4="","",IFERROR(MAX(0,N(Datos!E4)),0)) | E4: =IF(Datos!A4="","",IFERROR(MAX(0,N(Datos!F4)),0)) | F4: =IF(Datos!A4="","",IFERROR(MAX(0,N(Datos!G4)),0)) | G4: =IF(Datos!A4="","",IFERROR(MAX(0,N(Datos!H4)),0)) | H4: =IF(Datos!A4="","",IFERROR(MAX(0,N(Datos!I4)),0)) | J4: =IF(Datos!A4="","",IF(MAX(C$2:C$301)-MIN(C$2:C$301)<0.000000001,0.5,(C4-MIN(C$2:C$301))/(MAX(C$2:C$301)-MIN(C$2:C$301)))+0.000000001) | K4: =IF(Datos!A4="","",IF(MAX(D$2:D$301)-MIN(D$2:D$301)<0.000000001,0.5,(D4-MIN(D$2:D$301))/(MAX(D$2:D$301)-MIN(D$2:D$301)))+0.000000001) | L4: =IF(Datos!A4="","",IF(MAX(E$2:E$301)-MIN(E$2:E$301)<0.000000001,0.5,(E4-MIN(E$2:E$301))/(MAX(E$2:E$301)-MIN(E$2:E$301)))+0.000000001) | M4: =IF(Datos!A4="","",IF(MAX(F$2:F$301)-MIN(F$2:F$301)<0.000000001,0.5,(F4-MIN(F$2:F$301))/(MAX(F$2:F$301)-MIN(F$2:F$301)))+0.000000001) | N4: =IF(Datos!A4="","",IF(MAX(G$2:G$301)-MIN(G$2:G$301)<0.000000001,0.5,(G4-MIN(G$2:G$301))/(MAX(G$2:G$301)-MIN(G$2:G$301)))+0.000000001) | O4: =IF(Datos!A4="","",IF(MAX(H$2:H$301)-MIN(H$2:H$301)<0.000000001,0.5,(H4-MIN(H$2:H$301))/(MAX(H$2:H$301)-MIN(H$2:H$301)))+0.000000001) | Q4: =IF(Datos!A4="","",(J4/SUM(J$2:J$301))*LN(J4/SUM(J$2:J$301))) | R4: =IF(Datos!A4="","",(K4/SUM(K$2:K$301))*LN(K4/SUM(K$2:K$301))) | S4: =IF(Datos!A4="","",(L4/SUM(L$2:L$301))*LN(L4/SUM(L$2:L$301))) | T4: =IF(Datos!A4="","",(M4/SUM(M$2:M$301))*LN(M4/SUM(M$2:M$301))) | U4: =IF(Datos!A4="","",(N4/SUM(N$2:N$301))*LN(N4/SUM(N$2:N$301))) | V4: =IF(Datos!A4="","",(O4/SUM(O$2:O$301))*LN(O4/SUM(O$2:O$301))) | X4: =IF(Datos!A4="","",IF(SUMSQ(C$2:C$301)=0,0,C4/SQRT(SUMSQ(C$2:C$301)))*$BE$2) | Y4: =IF(Datos!A4="","",IF(SUMSQ(D$2:D$301)=0,0,D4/SQRT(SUMSQ(D$2:D$301)))*$BE$3) | Z4: =IF(Datos!A4="","",IF(SUMSQ(E$2:E$301)=0,0,E4/SQRT(SUMSQ(E$2:E$301)))*$BE$4) | AA4: =IF(Datos!A4="","",IF(SUMSQ(F$2:F$301)=0,0,F4/SQRT(SUMSQ(F$2:F$301)))*$BE$5) | AB4: =IF(Datos!A4="","",IF(SUMSQ(G$2:G$301)=0,0,G4/SQRT(SUMSQ(G$2:G$301)))*$BE$6) | AC4: =IF(Datos!A4="","",IF(SUMSQ(H$2:H$301)=0,0,H4/SQRT(SUMSQ(H$2:H$301)))*$BE$7) | AE4: =IF(Datos!A4="","",SQRT(SUMXMY2(X4:AC4,$X$303:$AC$303))) | AF4: =IF(Datos!A4="","",SQRT(SUMXMY2(X4:AC4,$X$304:$AC$304))) | AG4: =IF(Datos!A4="","",IF(AE4+AF4<0.000000001,0.5,AF4/(AE4+AF4))) | AH4: =IF(Datos!A4="","",AG4*MAX(C4*D4,1)) | AI4: =IF(Datos!A4="","",SUMIF($AH$2:$AH$301,">="&AH4,$AH$2:$AH$301)/SUM($AH$2:$AH$301)) | AJ4: =IF(Datos!A4="","",IF(AI4<=Parametros!$B$13,"A",IF(AI4<=Parametros!$B$14,"B","C"))) | AK4: =IF(Datos!A4="","",VLOOKUP(AJ4,Parametros!$A$8:$C$10,2,FALSE)) | AL4: =IF(Datos!A4="","",VLOOKUP(AJ4,Parametros!$A$8:$C$10,3,FALSE)) | AM4: =IF(Datos!A4="","",NORMSINV(AK4)) | AN4: =IF(Datos!A4="","",D4/Parametros!$B$4) | AO4: =IF(Datos!A4="","",MAX(0,ROUNDUP(AM4*(AN4*Parametros!$B$3)*SQRT((AL4+E4)),0))) | AP4: =IF(Datos!A4="","",MAX(1,ROUNDUP(AN4*(AL4+E4)+AM4*(AN4*Parametros!$B$3)*SQRT((AL4+E4)),0))) | AQ4: =IF(Datos!A4="","",IF(Datos!J4="","",Datos!J4)) | AR4: =IF(OR(Datos!A4="",AQ4=""),"",MAX(0,AQ4-AP4)) | AS4: =IF(OR(Datos!A4="",AQ4=""),"",AR4*C4) | AT4: =IF(OR(Datos!A4="",AQ4=""),"",IF(AQ4<AO4,"SI","")) | AU4: =IF(Datos!A4="","",IF(AT4="SI","Reponer ahora",IF(AND(AQ4<>"",AR4>0),"Bajar "&TEXT(AR4,"#,##0")&" un.","En rango"))) | BA4: Lead time (dias) | BB4: beneficio | BC4: =IF($BE$10<2,1,-1/LN($BE$10)*SUM(S$2:S$301)) | BD4: =MAX(0,1-BC4) | BE4: =IF(SUM($BD$2:$BD$7)<0.000000001,1/6,BD4/SUM($BD$2:$BD$7))
A5: =IF(Datos!A5="","",Datos!A5) | B5: =IF(Datos!A5="","",Datos!B5) | C5: =IF(Datos!A5="","",IFERROR(MAX(0,N(Datos!D5)),0)) | D5: =IF(Datos!A5="","",IFERROR(MAX(0,N(Datos!E5)),0)) | E5: =IF(Datos!A5="","",IFERROR(MAX(0,N(Datos!F5)),0)) | F5: =IF(Datos!A5="","",IFERROR(MAX(0,N(Datos!G5)),0)) | G5: =IF(Datos!A5="","",IFERROR(MAX(0,N(Datos!H5)),0)) | H5: =IF(Datos!A5="","",IFERROR(MAX(0,N(Datos!I5)),0)) | J5: =IF(Datos!A5="","",IF(MAX(C$2:C$301)-MIN(C$2:C$301)<0.000000001,0.5,(C5-MIN(C$2:C$301))/(MAX(C$2:C$301)-MIN(C$2:C$301)))+0.000000001) | K5: =IF(Datos!A5="","",IF(MAX(D$2:D$301)-MIN(D$2:D$301)<0.000000001,0.5,(D5-MIN(D$2:D$301))/(MAX(D$2:D$301)-MIN(D$2:D$301)))+0.000000001) | L5: =IF(Datos!A5="","",IF(MAX(E$2:E$301)-MIN(E$2:E$301)<0.000000001,0.5,(E5-MIN(E$2:E$301))/(MAX(E$2:E$301)-MIN(E$2:E$301)))+0.000000001) | M5: =IF(Datos!A5="","",IF(MAX(F$2:F$301)-MIN(F$2:F$301)<0.000000001,0.5,(F5-MIN(F$2:F$301))/(MAX(F$2:F$301)-MIN(F$2:F$301)))+0.000000001) | N5: =IF(Datos!A5="","",IF(MAX(G$2:G$301)-MIN(G$2:G$301)<0.000000001,0.5,(G5-MIN(G$2:G$301))/(MAX(G$2:G$301)-MIN(G$2:G$301)))+0.000000001) | O5: =IF(Datos!A5="","",IF(MAX(H$2:H$301)-MIN(H$2:H$301)<0.000000001,0.5,(H5-MIN(H$2:H$301))/(MAX(H$2:H$301)-MIN(H$2:H$301)))+0.000000001) | Q5: =IF(Datos!A5="","",(J5/SUM(J$2:J$301))*LN(J5/SUM(J$2:J$301))) | R5: =IF(Datos!A5="","",(K5/SUM(K$2:K$301))*LN(K5/SUM(K$2:K$301))) | S5: =IF(Datos!A5="","",(L5/SUM(L$2:L$301))*LN(L5/SUM(L$2:L$301))) | T5: =IF(Datos!A5="","",(M5/SUM(M$2:M$301))*LN(M5/SUM(M$2:M$301))) | U5: =IF(Datos!A5="","",(N5/SUM(N$2:N$301))*LN(N5/SUM(N$2:N$301))) | V5: =IF(Datos!A5="","",(O5/SUM(O$2:O$301))*LN(O5/SUM(O$2:O$301))) | X5: =IF(Datos!A5="","",IF(SUMSQ(C$2:C$301)=0,0,C5/SQRT(SUMSQ(C$2:C$301)))*$BE$2) | Y5: =IF(Datos!A5="","",IF(SUMSQ(D$2:D$301)=0,0,D5/SQRT(SUMSQ(D$2:D$301)))*$BE$3) | Z5: =IF(Datos!A5="","",IF(SUMSQ(E$2:E$301)=0,0,E5/SQRT(SUMSQ(E$2:E$301)))*$BE$4) | AA5: =IF(Datos!A5="","",IF(SUMSQ(F$2:F$301)=0,0,F5/SQRT(SUMSQ(F$2:F$301)))*$BE$5) | AB5: =IF(Datos!A5="","",IF(SUMSQ(G$2:G$301)=0,0,G5/SQRT(SUMSQ(G$2:G$301)))*$BE$6) | AC5: =IF(Datos!A5="","",IF(SUMSQ(H$2:H$301)=0,0,H5/SQRT(SUMSQ(H$2:H$301)))*$BE$7) | AE5: =IF(Datos!A5="","",SQRT(SUMXMY2(X5:AC5,$X$303:$AC$303))) | AF5: =IF(Datos!A5="","",SQRT(SUMXMY2(X5:AC5,$X$304:$AC$304))) | AG5: =IF(Datos!A5="","",IF(AE5+AF5<0.000000001,0.5,AF5/(AE5+AF5))) | AH5: =IF(Datos!A5="","",AG5*MAX(C5*D5,1)) | AI5: =IF(Datos!A5="","",SUMIF($AH$2:$AH$301,">="&AH5,$AH$2:$AH$301)/SUM($AH$2:$AH$301)) | AJ5: =IF(Datos!A5="","",IF(AI5<=Parametros!$B$13,"A",IF(AI5<=Parametros!$B$14,"B","C"))) | AK5: =IF(Datos!A5="","",VLOOKUP(AJ5,Parametros!$A$8:$C$10,2,FALSE)) | AL5: =IF(Datos!A5="","",VLOOKUP(AJ5,Parametros!$A$8:$C$10,3,FALSE)) | AM5: =IF(Datos!A5="","",NORMSINV(AK5)) | AN5: =IF(Datos!A5="","",D5/Parametros!$B$4) | AO5: =IF(Datos!A5="","",MAX(0,ROUNDUP(AM5*(AN5*Parametros!$B$3)*SQRT((AL5+E5)),0))) | AP5: =IF(Datos!A5="","",MAX(1,ROUNDUP(AN5*(AL5+E5)+AM5*(AN5*Parametros!$B$3)*SQRT((AL5+E5)),0))) | AQ5: =IF(Datos!A5="","",IF(Datos!J5="","",Datos!J5)) | AR5: =IF(OR(Datos!A5="",AQ5=""),"",MAX(0,AQ5-AP5)) | AS5: =IF(OR(Datos!A5="",AQ5=""),"",AR5*C5) | AT5: =IF(OR(Datos!A5="",AQ5=""),"",IF(AQ5<AO5,"SI","")) | AU5: =IF(Datos!A5="","",IF(AT5="SI","Reponer ahora",IF(AND(AQ5<>"",AR5>0),"Bajar "&TEXT(AR5,"#,##0")&" un.","En rango"))) | BA5: Criticidad equipo | BB5: beneficio | BC5: =IF($BE$10<2,1,-1/LN($BE$10)*SUM(T$2:T$301)) | BD5: =MAX(0,1-BC5) | BE5: =IF(SUM($BD$2:$BD$7)<0.000000001,1/6,BD5/SUM($BD$2:$BD$7))
A6: =IF(Datos!A6="","",Datos!A6) | B6: =IF(Datos!A6="","",Datos!B6) | C6: =IF(Datos!A6="","",IFERROR(MAX(0,N(Datos!D6)),0)) | D6: =IF(Datos!A6="","",IFERROR(MAX(0,N(Datos!E6)),0)) | E6: =IF(Datos!A6="","",IFERROR(MAX(0,N(Datos!F6)),0)) | F6: =IF(Datos!A6="","",IFERROR(MAX(0,N(Datos!G6)),0)) | G6: =IF(Datos!A6="","",IFERROR(MAX(0,N(Datos!H6)),0)) | H6: =IF(Datos!A6="","",IFERROR(MAX(0,N(Datos!I6)),0)) | J6: =IF(Datos!A6="","",IF(MAX(C$2:C$301)-MIN(C$2:C$301)<0.000000001,0.5,(C6-MIN(C$2:C$301))/(MAX(C$2:C$301)-MIN(C$2:C$301)))+0.000000001) | K6: =IF(Datos!A6="","",IF(MAX(D$2:D$301)-MIN(D$2:D$301)<0.000000001,0.5,(D6-MIN(D$2:D$301))/(MAX(D$2:D$301)-MIN(D$2:D$301)))+0.000000001) | L6: =IF(Datos!A6="","",IF(MAX(E$2:E$301)-MIN(E$2:E$301)<0.000000001,0.5,(E6-MIN(E$2:E$301))/(MAX(E$2:E$301)-MIN(E$2:E$301)))+0.000000001) | M6: =IF(Datos!A6="","",IF(MAX(F$2:F$301)-MIN(F$2:F$301)<0.000000001,0.5,(F6-MIN(F$2:F$301))/(MAX(F$2:F$301)-MIN(F$2:F$301)))+0.000000001) | N6: =IF(Datos!A6="","",IF(MAX(G$2:G$301)-MIN(G$2:G$301)<0.000000001,0.5,(G6-MIN(G$2:G$301))/(MAX(G$2:G$301)-MIN(G$2:G$301)))+0.000000001) | O6: =IF(Datos!A6="","",IF(MAX(H$2:H$301)-MIN(H$2:H$301)<0.000000001,0.5,(H6-MIN(H$2:H$301))/(MAX(H$2:H$301)-MIN(H$2:H$301)))+0.000000001) | Q6: =IF(Datos!A6="","",(J6/SUM(J$2:J$301))*LN(J6/SUM(J$2:J$301))) | R6: =IF(Datos!A6="","",(K6/SUM(K$2:K$301))*LN(K6/SUM(K$2:K$301))) | S6: =IF(Datos!A6="","",(L6/SUM(L$2:L$301))*LN(L6/SUM(L$2:L$301))) | T6: =IF(Datos!A6="","",(M6/SUM(M$2:M$301))*LN(M6/SUM(M$2:M$301))) | U6: =IF(Datos!A6="","",(N6/SUM(N$2:N$301))*LN(N6/SUM(N$2:N$301))) | V6: =IF(Datos!A6="","",(O6/SUM(O$2:O$301))*LN(O6/SUM(O$2:O$301))) | X6: =IF(Datos!A6="","",IF(SUMSQ(C$2:C$301)=0,0,C6/SQRT(SUMSQ(C$2:C$301)))*$BE$2) | Y6: =IF(Datos!A6="","",IF(SUMSQ(D$2:D$301)=0,0,D6/SQRT(SUMSQ(D$2:D$301)))*$BE$3) | Z6: =IF(Datos!A6="","",IF(SUMSQ(E$2:E$301)=0,0,E6/SQRT(SUMSQ(E$2:E$301)))*$BE$4) | AA6: =IF(Datos!A6="","",IF(SUMSQ(F$2:F$301)=0,0,F6/SQRT(SUMSQ(F$2:F$301)))*$BE$5) | AB6: =IF(Datos!A6="","",IF(SUMSQ(G$2:G$301)=0,0,G6/SQRT(SUMSQ(G$2:G$301)))*$BE$6) | AC6: =IF(Datos!A6="","",IF(SUMSQ(H$2:H$301)=0,0,H6/SQRT(SUMSQ(H$2:H$301)))*$BE$7) | AE6: =IF(Datos!A6="","",SQRT(SUMXMY2(X6:AC6,$X$303:$AC$303))) | AF6: =IF(Datos!A6="","",SQRT(SUMXMY2(X6:AC6,$X$304:$AC$304))) | AG6: =IF(Datos!A6="","",IF(AE6+AF6<0.000000001,0.5,AF6/(AE6+AF6))) | AH6: =IF(Datos!A6="","",AG6*MAX(C6*D6,1)) | AI6: =IF(Datos!A6="","",SUMIF($AH$2:$AH$301,">="&AH6,$AH$2:$AH$301)/SUM($AH$2:$AH$301)) | AJ6: =IF(Datos!A6="","",IF(AI6<=Parametros!$B$13,"A",IF(AI6<=Parametros!$B$14,"B","C"))) | AK6: =IF(Datos!A6="","",VLOOKUP(AJ6,Parametros!$A$8:$C$10,2,FALSE)) | AL6: =IF(Datos!A6="","",VLOOKUP(AJ6,Parametros!$A$8:$C$10,3,FALSE)) | AM6: =IF(Datos!A6="","",NORMSINV(AK6)) | AN6: =IF(Datos!A6="","",D6/Parametros!$B$4) | AO6: =IF(Datos!A6="","",MAX(0,ROUNDUP(AM6*(AN6*Parametros!$B$3)*SQRT((AL6+E6)),0))) | AP6: =IF(Datos!A6="","",MAX(1,ROUNDUP(AN6*(AL6+E6)+AM6*(AN6*Parametros!$B$3)*SQRT((AL6+E6)),0))) | AQ6: =IF(Datos!A6="","",IF(Datos!J6="","",Datos!J6)) | AR6: =IF(OR(Datos!A6="",AQ6=""),"",MAX(0,AQ6-AP6)) | AS6: =IF(OR(Datos!A6="",AQ6=""),"",AR6*C6) | AT6: =IF(OR(Datos!A6="",AQ6=""),"",IF(AQ6<AO6,"SI","")) | AU6: =IF(Datos!A6="","",IF(AT6="SI","Reponer ahora",IF(AND(AQ6<>"",AR6>0),"Bajar "&TEXT(AR6,"#,##0")&" un.","En rango"))) | BA6: Horas parada | BB6: beneficio | BC6: =IF($BE$10<2,1,-1/LN($BE$10)*SUM(U$2:U$301)) | BD6: =MAX(0,1-BC6) | BE6: =IF(SUM($BD$2:$BD$7)<0.000000001,1/6,BD6/SUM($BD$2:$BD$7))
A7: =IF(Datos!A7="","",Datos!A7) | B7: =IF(Datos!A7="","",Datos!B7) | C7: =IF(Datos!A7="","",IFERROR(MAX(0,N(Datos!D7)),0)) | D7: =IF(Datos!A7="","",IFERROR(MAX(0,N(Datos!E7)),0)) | E7: =IF(Datos!A7="","",IFERROR(MAX(0,N(Datos!F7)),0)) | F7: =IF(Datos!A7="","",IFERROR(MAX(0,N(Datos!G7)),0)) | G7: =IF(Datos!A7="","",IFERROR(MAX(0,N(Datos!H7)),0)) | H7: =IF(Datos!A7="","",IFERROR(MAX(0,N(Datos!I7)),0)) | J7: =IF(Datos!A7="","",IF(MAX(C$2:C$301)-MIN(C$2:C$301)<0.000000001,0.5,(C7-MIN(C$2:C$301))/(MAX(C$2:C$301)-MIN(C$2:C$301)))+0.000000001) | K7: =IF(Datos!A7="","",IF(MAX(D$2:D$301)-MIN(D$2:D$301)<0.000000001,0.5,(D7-MIN(D$2:D$301))/(MAX(D$2:D$301)-MIN(D$2:D$301)))+0.000000001) | L7: =IF(Datos!A7="","",IF(MAX(E$2:E$301)-MIN(E$2:E$301)<0.000000001,0.5,(E7-MIN(E$2:E$301))/(MAX(E$2:E$301)-MIN(E$2:E$301)))+0.000000001) | M7: =IF(Datos!A7="","",IF(MAX(F$2:F$301)-MIN(F$2:F$301)<0.000000001,0.5,(F7-MIN(F$2:F$301))/(MAX(F$2:F$301)-MIN(F$2:F$301)))+0.000000001) | N7: =IF(Datos!A7="","",IF(MAX(G$2:G$301)-MIN(G$2:G$301)<0.000000001,0.5,(G7-MIN(G$2:G$301))/(MAX(G$2:G$301)-MIN(G$2:G$301)))+0.000000001) | O7: =IF(Datos!A7="","",IF(MAX(H$2:H$301)-MIN(H$2:H$301)<0.000000001,0.5,(H7-MIN(H$2:H$301))/(MAX(H$2:H$301)-MIN(H$2:H$301)))+0.000000001) | Q7: =IF(Datos!A7="","",(J7/SUM(J$2:J$301))*LN(J7/SUM(J$2:J$301))) | R7: =IF(Datos!A7="","",(K7/SUM(K$2:K$301))*LN(K7/SUM(K$2:K$301))) | S7: =IF(Datos!A7="","",(L7/SUM(L$2:L$301))*LN(L7/SUM(L$2:L$301))) | T7: =IF(Datos!A7="","",(M7/SUM(M$2:M$301))*LN(M7/SUM(M$2:M$301))) | U7: =IF(Datos!A7="","",(N7/SUM(N$2:N$301))*LN(N7/SUM(N$2:N$301))) | V7: =IF(Datos!A7="","",(O7/SUM(O$2:O$301))*LN(O7/SUM(O$2:O$301))) | X7: =IF(Datos!A7="","",IF(SUMSQ(C$2:C$301)=0,0,C7/SQRT(SUMSQ(C$2:C$301)))*$BE$2) | Y7: =IF(Datos!A7="","",IF(SUMSQ(D$2:D$301)=0,0,D7/SQRT(SUMSQ(D$2:D$301)))*$BE$3) | Z7: =IF(Datos!A7="","",IF(SUMSQ(E$2:E$301)=0,0,E7/SQRT(SUMSQ(E$2:E$301)))*$BE$4) | AA7: =IF(Datos!A7="","",IF(SUMSQ(F$2:F$301)=0,0,F7/SQRT(SUMSQ(F$2:F$301)))*$BE$5) | AB7: =IF(Datos!A7="","",IF(SUMSQ(G$2:G$301)=0,0,G7/SQRT(SUMSQ(G$2:G$301)))*$BE$6) | AC7: =IF(Datos!A7="","",IF(SUMSQ(H$2:H$301)=0,0,H7/SQRT(SUMSQ(H$2:H$301)))*$BE$7) | AE7: =IF(Datos!A7="","",SQRT(SUMXMY2(X7:AC7,$X$303:$AC$303))) | AF7: =IF(Datos!A7="","",SQRT(SUMXMY2(X7:AC7,$X$304:$AC$304))) | AG7: =IF(Datos!A7="","",IF(AE7+AF7<0.000000001,0.5,AF7/(AE7+AF7))) | AH7: =IF(Datos!A7="","",AG7*MAX(C7*D7,1)) | AI7: =IF(Datos!A7="","",SUMIF($AH$2:$AH$301,">="&AH7,$AH$2:$AH$301)/SUM($AH$2:$AH$301)) | AJ7: =IF(Datos!A7="","",IF(AI7<=Parametros!$B$13,"A",IF(AI7<=Parametros!$B$14,"B","C"))) | AK7: =IF(Datos!A7="","",VLOOKUP(AJ7,Parametros!$A$8:$C$10,2,FALSE)) | AL7: =IF(Datos!A7="","",VLOOKUP(AJ7,Parametros!$A$8:$C$10,3,FALSE)) | AM7: =IF(Datos!A7="","",NORMSINV(AK7)) | AN7: =IF(Datos!A7="","",D7/Parametros!$B$4) | AO7: =IF(Datos!A7="","",MAX(0,ROUNDUP(AM7*(AN7*Parametros!$B$3)*SQRT((AL7+E7)),0))) | AP7: =IF(Datos!A7="","",MAX(1,ROUNDUP(AN7*(AL7+E7)+AM7*(AN7*Parametros!$B$3)*SQRT((AL7+E7)),0))) | AQ7: =IF(Datos!A7="","",IF(Datos!J7="","",Datos!J7)) | AR7: =IF(OR(Datos!A7="",AQ7=""),"",MAX(0,AQ7-AP7)) | AS7: =IF(OR(Datos!A7="",AQ7=""),"",AR7*C7) | AT7: =IF(OR(Datos!A7="",AQ7=""),"",IF(AQ7<AO7,"SI","")) | AU7: =IF(Datos!A7="","",IF(AT7="SI","Reponer ahora",IF(AND(AQ7<>"",AR7>0),"Bajar "&TEXT(AR7,"#,##0")&" un.","En rango"))) | BA7: N proveedores | BB7: costo | BC7: =IF($BE$10<2,1,-1/LN($BE$10)*SUM(V$2:V$301)) | BD7: =MAX(0,1-BC7) | BE7: =IF(SUM($BD$2:$BD$7)<0.000000001,1/6,BD7/SUM($BD$2:$BD$7))
A8: =IF(Datos!A8="","",Datos!A8) | B8: =IF(Datos!A8="","",Datos!B8) | C8: =IF(Datos!A8="","",IFERROR(MAX(0,N(Datos!D8)),0)) | D8: =IF(Datos!A8="","",IFERROR(MAX(0,N(Datos!E8)),0)) | E8: =IF(Datos!A8="","",IFERROR(MAX(0,N(Datos!F8)),0)) | F8: =IF(Datos!A8="","",IFERROR(MAX(0,N(Datos!G8)),0)) | G8: =IF(Datos!A8="","",IFERROR(MAX(0,N(Datos!H8)),0)) | H8: =IF(Datos!A8="","",IFERROR(MAX(0,N(Datos!I8)),0)) | J8: =IF(Datos!A8="","",IF(MAX(C$2:C$301)-MIN(C$2:C$301)<0.000000001,0.5,(C8-MIN(C$2:C$301))/(MAX(C$2:C$301)-MIN(C$2:C$301)))+0.000000001) | K8: =IF(Datos!A8="","",IF(MAX(D$2:D$301)-MIN(D$2:D$301)<0.000000001,0.5,(D8-MIN(D$2:D$301))/(MAX(D$2:D$301)-MIN(D$2:D$301)))+0.000000001) | L8: =IF(Datos!A8="","",IF(MAX(E$2:E$301)-MIN(E$2:E$301)<0.000000001,0.5,(E8-MIN(E$2:E$301))/(MAX(E$2:E$301)-MIN(E$2:E$301)))+0.000000001) | M8: =IF(Datos!A8="","",IF(MAX(F$2:F$301)-MIN(F$2:F$301)<0.000000001,0.5,(F8-MIN(F$2:F$301))/(MAX(F$2:F$301)-MIN(F$2:F$301)))+0.000000001) | N8: =IF(Datos!A8="","",IF(MAX(G$2:G$301)-MIN(G$2:G$301)<0.000000001,0.5,(G8-MIN(G$2:G$301))/(MAX(G$2:G$301)-MIN(G$2:G$301)))+0.000000001) | O8: =IF(Datos!A8="","",IF(MAX(H$2:H$301)-MIN(H$2:H$301)<0.000000001,0.5,(H8-MIN(H$2:H$301))/(MAX(H$2:H$301)-MIN(H$2:H$301)))+0.000000001) | Q8: =IF(Datos!A8="","",(J8/SUM(J$2:J$301))*LN(J8/SUM(J$2:J$301))) | R8: =IF(Datos!A8="","",(K8/SUM(K$2:K$301))*LN(K8/SUM(K$2:K$301))) | S8: =IF(Datos!A8="","",(L8/SUM(L$2:L$301))*LN(L8/SUM(L$2:L$301))) | T8: =IF(Datos!A8="","",(M8/SUM(M$2:M$301))*LN(M8/SUM(M$2:M$301))) | U8: =IF(Datos!A8="","",(N8/SUM(N$2:N$301))*LN(N8/SUM(N$2:N$301))) | V8: =IF(Datos!A8="","",(O8/SUM(O$2:O$301))*LN(O8/SUM(O$2:O$301))) | X8: =IF(Datos!A8="","",IF(SUMSQ(C$2:C$301)=0,0,C8/SQRT(SUMSQ(C$2:C$301)))*$BE$2) | Y8: =IF(Datos!A8="","",IF(SUMSQ(D$2:D$301)=0,0,D8/SQRT(SUMSQ(D$2:D$301)))*$BE$3) | Z8: =IF(Datos!A8="","",IF(SUMSQ(E$2:E$301)=0,0,E8/SQRT(SUMSQ(E$2:E$301)))*$BE$4) | AA8: =IF(Datos!A8="","",IF(SUMSQ(F$2:F$301)=0,0,F8/SQRT(SUMSQ(F$2:F$301)))*$BE$5) | AB8: =IF(Datos!A8="","",IF(SUMSQ(G$2:G$301)=0,0,G8/SQRT(SUMSQ(G$2:G$301)))*$BE$6) | AC8: =IF(Datos!A8="","",IF(SUMSQ(H$2:H$301)=0,0,H8/SQRT(SUMSQ(H$2:H$301)))*$BE$7) | AE8: =IF(Datos!A8="","",SQRT(SUMXMY2(X8:AC8,$X$303:$AC$303))) | AF8: =IF(Datos!A8="","",SQRT(SUMXMY2(X8:AC8,$X$304:$AC$304))) | AG8: =IF(Datos!A8="","",IF(AE8+AF8<0.000000001,0.5,AF8/(AE8+AF8))) | AH8: =IF(Datos!A8="","",AG8*MAX(C8*D8,1)) | AI8: =IF(Datos!A8="","",SUMIF($AH$2:$AH$301,">="&AH8,$AH$2:$AH$301)/SUM($AH$2:$AH$301)) | AJ8: =IF(Datos!A8="","",IF(AI8<=Parametros!$B$13,"A",IF(AI8<=Parametros!$B$14,"B","C"))) | AK8: =IF(Datos!A8="","",VLOOKUP(AJ8,Parametros!$A$8:$C$10,2,FALSE)) | AL8: =IF(Datos!A8="","",VLOOKUP(AJ8,Parametros!$A$8:$C$10,3,FALSE)) | AM8: =IF(Datos!A8="","",NORMSINV(AK8)) | AN8: =IF(Datos!A8="","",D8/Parametros!$B$4) | AO8: =IF(Datos!A8="","",MAX(0,ROUNDUP(AM8*(AN8*Parametros!$B$3)*SQRT((AL8+E8)),0))) | AP8: =IF(Datos!A8="","",MAX(1,ROUNDUP(AN8*(AL8+E8)+AM8*(AN8*Parametros!$B$3)*SQRT((AL8+E8)),0))) | AQ8: =IF(Datos!A8="","",IF(Datos!J8="","",Datos!J8)) | AR8: =IF(OR(Datos!A8="",AQ8=""),"",MAX(0,AQ8-AP8)) | AS8: =IF(OR(Datos!A8="",AQ8=""),"",AR8*C8) | AT8: =IF(OR(Datos!A8="",AQ8=""),"",IF(AQ8<AO8,"SI","")) | AU8: =IF(Datos!A8="","",IF(AT8="SI","Reponer ahora",IF(AND(AQ8<>"",AR8>0),"Bajar "&TEXT(AR8,"#,##0")&" un.","En rango")))
A9: =IF(Datos!A9="","",Datos!A9) | B9: =IF(Datos!A9="","",Datos!B9) | C9: =IF(Datos!A9="","",IFERROR(MAX(0,N(Datos!D9)),0)) | D9: =IF(Datos!A9="","",IFERROR(MAX(0,N(Datos!E9)),0)) | E9: =IF(Datos!A9="","",IFERROR(MAX(0,N(Datos!F9)),0)) | F9: =IF(Datos!A9="","",IFERROR(MAX(0,N(Datos!G9)),0)) | G9: =IF(Datos!A9="","",IFERROR(MAX(0,N(Datos!H9)),0)) | H9: =IF(Datos!A9="","",IFERROR(MAX(0,N(Datos!I9)),0)) | J9: =IF(Datos!A9="","",IF(MAX(C$2:C$301)-MIN(C$2:C$301)<0.000000001,0.5,(C9-MIN(C$2:C$301))/(MAX(C$2:C$301)-MIN(C$2:C$301)))+0.000000001) | K9: =IF(Datos!A9="","",IF(MAX(D$2:D$301)-MIN(D$2:D$301)<0.000000001,0.5,(D9-MIN(D$2:D$301))/(MAX(D$2:D$301)-MIN(D$2:D$301)))+0.000000001) | L9: =IF(Datos!A9="","",IF(MAX(E$2:E$301)-MIN(E$2:E$301)<0.000000001,0.5,(E9-MIN(E$2:E$301))/(MAX(E$2:E$301)-MIN(E$2:E$301)))+0.000000001) | M9: =IF(Datos!A9="","",IF(MAX(F$2:F$301)-MIN(F$2:F$301)<0.000000001,0.5,(F9-MIN(F$2:F$301))/(MAX(F$2:F$301)-MIN(F$2:F$301)))+0.000000001) | N9: =IF(Datos!A9="","",IF(MAX(G$2:G$301)-MIN(G$2:G$301)<0.000000001,0.5,(G9-MIN(G$2:G$301))/(MAX(G$2:G$301)-MIN(G$2:G$301)))+0.000000001) | O9: =IF(Datos!A9="","",IF(MAX(H$2:H$301)-MIN(H$2:H$301)<0.000000001,0.5,(H9-MIN(H$2:H$301))/(MAX(H$2:H$301)-MIN(H$2:H$301)))+0.000000001) | Q9: =IF(Datos!A9="","",(J9/SUM(J$2:J$301))*LN(J9/SUM(J$2:J$301))) | R9: =IF(Datos!A9="","",(K9/SUM(K$2:K$301))*LN(K9/SUM(K$2:K$301))) | S9: =IF(Datos!A9="","",(L9/SUM(L$2:L$301))*LN(L9/SUM(L$2:L$301))) | T9: =IF(Datos!A9="","",(M9/SUM(M$2:M$301))*LN(M9/SUM(M$2:M$301))) | U9: =IF(Datos!A9="","",(N9/SUM(N$2:N$301))*LN(N9/SUM(N$2:N$301))) | V9: =IF(Datos!A9="","",(O9/SUM(O$2:O$301))*LN(O9/SUM(O$2:O$301))) | X9: =IF(Datos!A9="","",IF(SUMSQ(C$2:C$301)=0,0,C9/SQRT(SUMSQ(C$2:C$301)))*$BE$2) | Y9: =IF(Datos!A9="","",IF(SUMSQ(D$2:D$301)=0,0,D9/SQRT(SUMSQ(D$2:D$301)))*$BE$3) | Z9: =IF(Datos!A9="","",IF(SUMSQ(E$2:E$301)=0,0,E9/SQRT(SUMSQ(E$2:E$301)))*$BE$4) | AA9: =IF(Datos!A9="","",IF(SUMSQ(F$2:F$301)=0,0,F9/SQRT(SUMSQ(F$2:F$301)))*$BE$5) | AB9: =IF(Datos!A9="","",IF(SUMSQ(G$2:G$301)=0,0,G9/SQRT(SUMSQ(G$2:G$301)))*$BE$6) | AC9: =IF(Datos!A9="","",IF(SUMSQ(H$2:H$301)=0,0,H9/SQRT(SUMSQ(H$2:H$301)))*$BE$7) | AE9: =IF(Datos!A9="","",SQRT(SUMXMY2(X9:AC9,$X$303:$AC$303))) | AF9: =IF(Datos!A9="","",SQRT(SUMXMY2(X9:AC9,$X$304:$AC$304))) | AG9: =IF(Datos!A9="","",IF(AE9+AF9<0.000000001,0.5,AF9/(AE9+AF9))) | AH9: =IF(Datos!A9="","",AG9*MAX(C9*D9,1)) | AI9: =IF(Datos!A9="","",SUMIF($AH$2:$AH$301,">="&AH9,$AH$2:$AH$301)/SUM($AH$2:$AH$301)) | AJ9: =IF(Datos!A9="","",IF(AI9<=Parametros!$B$13,"A",IF(AI9<=Parametros!$B$14,"B","C"))) | AK9: =IF(Datos!A9="","",VLOOKUP(AJ9,Parametros!$A$8:$C$10,2,FALSE)) | AL9: =IF(Datos!A9="","",VLOOKUP(AJ9,Parametros!$A$8:$C$10,3,FALSE)) | AM9: =IF(Datos!A9="","",NORMSINV(AK9)) | AN9: =IF(Datos!A9="","",D9/Parametros!$B$4) | AO9: =IF(Datos!A9="","",MAX(0,ROUNDUP(AM9*(AN9*Parametros!$B$3)*SQRT((AL9+E9)),0))) | AP9: =IF(Datos!A9="","",MAX(1,ROUNDUP(AN9*(AL9+E9)+AM9*(AN9*Parametros!$B$3)*SQRT((AL9+E9)),0))) | AQ9: =IF(Datos!A9="","",IF(Datos!J9="","",Datos!J9)) | AR9: =IF(OR(Datos!A9="",AQ9=""),"",MAX(0,AQ9-AP9)) | AS9: =IF(OR(Datos!A9="",AQ9=""),"",AR9*C9) | AT9: =IF(OR(Datos!A9="",AQ9=""),"",IF(AQ9<AO9,"SI","")) | AU9: =IF(Datos!A9="","",IF(AT9="SI","Reponer ahora",IF(AND(AQ9<>"",AR9>0),"Bajar "&TEXT(AR9,"#,##0")&" un.","En rango")))
A10: =IF(Datos!A10="","",Datos!A10) | B10: =IF(Datos!A10="","",Datos!B10) | C10: =IF(Datos!A10="","",IFERROR(MAX(0,N(Datos!D10)),0)) | D10: =IF(Datos!A10="","",IFERROR(MAX(0,N(Datos!E10)),0)) | E10: =IF(Datos!A10="","",IFERROR(MAX(0,N(Datos!F10)),0)) | F10: =IF(Datos!A10="","",IFERROR(MAX(0,N(Datos!G10)),0)) | G10: =IF(Datos!A10="","",IFERROR(MAX(0,N(Datos!H10)),0)) | H10: =IF(Datos!A10="","",IFERROR(MAX(0,N(Datos!I10)),0)) | J10: =IF(Datos!A10="","",IF(MAX(C$2:C$301)-MIN(C$2:C$301)<0.000000001,0.5,(C10-MIN(C$2:C$301))/(MAX(C$2:C$301)-MIN(C$2:C$301)))+0.000000001) | K10: =IF(Datos!A10="","",IF(MAX(D$2:D$301)-MIN(D$2:D$301)<0.000000001,0.5,(D10-MIN(D$2:D$301))/(MAX(D$2:D$301)-MIN(D$2:D$301)))+0.000000001) | L10: =IF(Datos!A10="","",IF(MAX(E$2:E$301)-MIN(E$2:E$301)<0.000000001,0.5,(E10-MIN(E$2:E$301))/(MAX(E$2:E$301)-MIN(E$2:E$301)))+0.000000001) | M10: =IF(Datos!A10="","",IF(MAX(F$2:F$301)-MIN(F$2:F$301)<0.000000001,0.5,(F10-MIN(F$2:F$301))/(MAX(F$2:F$301)-MIN(F$2:F$301)))+0.000000001) | N10: =IF(Datos!A10="","",IF(MAX(G$2:G$301)-MIN(G$2:G$301)<0.000000001,0.5,(G10-MIN(G$2:G$301))/(MAX(G$2:G$301)-MIN(G$2:G$301)))+0.000000001) | O10: =IF(Datos!A10="","",IF(MAX(H$2:H$301)-MIN(H$2:H$301)<0.000000001,0.5,(H10-MIN(H$2:H$301))/(MAX(H$2:H$301)-MIN(H$2:H$301)))+0.000000001) | Q10: =IF(Datos!A10="","",(J10/SUM(J$2:J$301))*LN(J10/SUM(J$2:J$301))) | R10: =IF(Datos!A10="","",(K10/SUM(K$2:K$301))*LN(K10/SUM(K$2:K$301))) | S10: =IF(Datos!A10="","",(L10/SUM(L$2:L$301))*LN(L10/SUM(L$2:L$301))) | T10: =IF(Datos!A10="","",(M10/SUM(M$2:M$301))*LN(M10/SUM(M$2:M$301))) | U10: =IF(Datos!A10="","",(N10/SUM(N$2:N$301))*LN(N10/SUM(N$2:N$301))) | V10: =IF(Datos!A10="","",(O10/SUM(O$2:O$301))*LN(O10/SUM(O$2:O$301))) | X10: =IF(Datos!A10="","",IF(SUMSQ(C$2:C$301)=0,0,C10/SQRT(SUMSQ(C$2:C$301)))*$BE$2) | Y10: =IF(Datos!A10="","",IF(SUMSQ(D$2:D$301)=0,0,D10/SQRT(SUMSQ(D$2:D$301)))*$BE$3) | Z10: =IF(Datos!A10="","",IF(SUMSQ(E$2:E$301)=0,0,E10/SQRT(SUMSQ(E$2:E$301)))*$BE$4) | AA10: =IF(Datos!A10="","",IF(SUMSQ(F$2:F$301)=0,0,F10/SQRT(SUMSQ(F$2:F$301)))*$BE$5) | AB10: =IF(Datos!A10="","",IF(SUMSQ(G$2:G$301)=0,0,G10/SQRT(SUMSQ(G$2:G$301)))*$BE$6) | AC10: =IF(Datos!A10="","",IF(SUMSQ(H$2:H$301)=0,0,H10/SQRT(SUMSQ(H$2:H$301)))*$BE$7) | AE10: =IF(Datos!A10="","",SQRT(SUMXMY2(X10:AC10,$X$303:$AC$303))) | AF10: =IF(Datos!A10="","",SQRT(SUMXMY2(X10:AC10,$X$304:$AC$304))) | AG10: =IF(Datos!A10="","",IF(AE10+AF10<0.000000001,0.5,AF10/(AE10+AF10))) | AH10: =IF(Datos!A10="","",AG10*MAX(C10*D10,1)) | AI10: =IF(Datos!A10="","",SUMIF($AH$2:$AH$301,">="&AH10,$AH$2:$AH$301)/SUM($AH$2:$AH$301)) | AJ10: =IF(Datos!A10="","",IF(AI10<=Parametros!$B$13,"A",IF(AI10<=Parametros!$B$14,"B","C"))) | AK10: =IF(Datos!A10="","",VLOOKUP(AJ10,Parametros!$A$8:$C$10,2,FALSE)) | AL10: =IF(Datos!A10="","",VLOOKUP(AJ10,Parametros!$A$8:$C$10,3,FALSE)) | AM10: =IF(Datos!A10="","",NORMSINV(AK10)) | AN10: =IF(Datos!A10="","",D10/Parametros!$B$4) | AO10: =IF(Datos!A10="","",MAX(0,ROUNDUP(AM10*(AN10*Parametros!$B$3)*SQRT((AL10+E10)),0))) | AP10: =IF(Datos!A10="","",MAX(1,ROUNDUP(AN10*(AL10+E10)+AM10*(AN10*Parametros!$B$3)*SQRT((AL10+E10)),0))) | AQ10: =IF(Datos!A10="","",IF(Datos!J10="","",Datos!J10)) | AR10: =IF(OR(Datos!A10="",AQ10=""),"",MAX(0,AQ10-AP10)) | AS10: =IF(OR(Datos!A10="",AQ10=""),"",AR10*C10) | AT10: =IF(OR(Datos!A10="",AQ10=""),"",IF(AQ10<AO10,"SI","")) | AU10: =IF(Datos!A10="","",IF(AT10="SI","Reponer ahora",IF(AND(AQ10<>"",AR10>0),"Bajar "&TEXT(AR10,"#,##0")&" un.","En rango"))) | BD10: Repuestos con datos | BE10: =COUNT(Datos!D2:D301)
A11: =IF(Datos!A11="","",Datos!A11) | B11: =IF(Datos!A11="","",Datos!B11) | C11: =IF(Datos!A11="","",IFERROR(MAX(0,N(Datos!D11)),0)) | D11: =IF(Datos!A11="","",IFERROR(MAX(0,N(Datos!E11)),0)) | E11: =IF(Datos!A11="","",IFERROR(MAX(0,N(Datos!F11)),0)) | F11: =IF(Datos!A11="","",IFERROR(MAX(0,N(Datos!G11)),0)) | G11: =IF(Datos!A11="","",IFERROR(MAX(0,N(Datos!H11)),0)) | H11: =IF(Datos!A11="","",IFERROR(MAX(0,N(Datos!I11)),0)) | J11: =IF(Datos!A11="","",IF(MAX(C$2:C$301)-MIN(C$2:C$301)<0.000000001,0.5,(C11-MIN(C$2:C$301))/(MAX(C$2:C$301)-MIN(C$2:C$301)))+0.000000001) | K11: =IF(Datos!A11="","",IF(MAX(D$2:D$301)-MIN(D$2:D$301)<0.000000001,0.5,(D11-MIN(D$2:D$301))/(MAX(D$2:D$301)-MIN(D$2:D$301)))+0.000000001) | L11: =IF(Datos!A11="","",IF(MAX(E$2:E$301)-MIN(E$2:E$301)<0.000000001,0.5,(E11-MIN(E$2:E$301))/(MAX(E$2:E$301)-MIN(E$2:E$301)))+0.000000001) | M11: =IF(Datos!A11="","",IF(MAX(F$2:F$301)-MIN(F$2:F$301)<0.000000001,0.5,(F11-MIN(F$2:F$301))/(MAX(F$2:F$301)-MIN(F$2:F$301)))+0.000000001) | N11: =IF(Datos!A11="","",IF(MAX(G$2:G$301)-MIN(G$2:G$301)<0.000000001,0.5,(G11-MIN(G$2:G$301))/(MAX(G$2:G$301)-MIN(G$2:G$301)))+0.000000001) | O11: =IF(Datos!A11="","",IF(MAX(H$2:H$301)-MIN(H$2:H$301)<0.000000001,0.5,(H11-MIN(H$2:H$301))/(MAX(H$2:H$301)-MIN(H$2:H$301)))+0.000000001) | Q11: =IF(Datos!A11="","",(J11/SUM(J$2:J$301))*LN(J11/SUM(J$2:J$301))) | R11: =IF(Datos!A11="","",(K11/SUM(K$2:K$301))*LN(K11/SUM(K$2:K$301))) | S11: =IF(Datos!A11="","",(L11/SUM(L$2:L$301))*LN(L11/SUM(L$2:L$301))) | T11: =IF(Datos!A11="","",(M11/SUM(M$2:M$301))*LN(M11/SUM(M$2:M$301))) | U11: =IF(Datos!A11="","",(N11/SUM(N$2:N$301))*LN(N11/SUM(N$2:N$301))) | V11: =IF(Datos!A11="","",(O11/SUM(O$2:O$301))*LN(O11/SUM(O$2:O$301))) | X11: =IF(Datos!A11="","",IF(SUMSQ(C$2:C$301)=0,0,C11/SQRT(SUMSQ(C$2:C$301)))*$BE$2) | Y11: =IF(Datos!A11="","",IF(SUMSQ(D$2:D$301)=0,0,D11/SQRT(SUMSQ(D$2:D$301)))*$BE$3) | Z11: =IF(Datos!A11="","",IF(SUMSQ(E$2:E$301)=0,0,E11/SQRT(SUMSQ(E$2:E$301)))*$BE$4) | AA11: =IF(Datos!A11="","",IF(SUMSQ(F$2:F$301)=0,0,F11/SQRT(SUMSQ(F$2:F$301)))*$BE$5) | AB11: =IF(Datos!A11="","",IF(SUMSQ(G$2:G$301)=0,0,G11/SQRT(SUMSQ(G$2:G$301)))*$BE$6) | AC11: =IF(Datos!A11="","",IF(SUMSQ(H$2:H$301)=0,0,H11/SQRT(SUMSQ(H$2:H$301)))*$BE$7) | AE11: =IF(Datos!A11="","",SQRT(SUMXMY2(X11:AC11,$X$303:$AC$303))) | AF11: =IF(Datos!A11="","",SQRT(SUMXMY2(X11:AC11,$X$304:$AC$304))) | AG11: =IF(Datos!A11="","",IF(AE11+AF11<0.000000001,0.5,AF11/(AE11+AF11))) | AH11: =IF(Datos!A11="","",AG11*MAX(C11*D11,1)) | AI11: =IF(Datos!A11="","",SUMIF($AH$2:$AH$301,">="&AH11,$AH$2:$AH$301)/SUM($AH$2:$AH$301)) | AJ11: =IF(Datos!A11="","",IF(AI11<=Parametros!$B$13,"A",IF(AI11<=Parametros!$B$14,"B","C"))) | AK11: =IF(Datos!A11="","",VLOOKUP(AJ11,Parametros!$A$8:$C$10,2,FALSE)) | AL11: =IF(Datos!A11="","",VLOOKUP(AJ11,Parametros!$A$8:$C$10,3,FALSE)) | AM11: =IF(Datos!A11="","",NORMSINV(AK11)) | AN11: =IF(Datos!A11="","",D11/Parametros!$B$4) | AO11: =IF(Datos!A11="","",MAX(0,ROUNDUP(AM11*(AN11*Parametros!$B$3)*SQRT((AL11+E11)),0))) | AP11: =IF(Datos!A11="","",MAX(1,ROUNDUP(AN11*(AL11+E11)+AM11*(AN11*Parametros!$B$3)*SQRT((AL11+E11)),0))) | AQ11: =IF(Datos!A11="","",IF(Datos!J11="","",Datos!J11)) | AR11: =IF(OR(Datos!A11="",AQ11=""),"",MAX(0,AQ11-AP11)) | AS11: =IF(OR(Datos!A11="",AQ11=""),"",AR11*C11) | AT11: =IF(OR(Datos!A11="",AQ11=""),"",IF(AQ11<AO11,"SI","")) | AU11: =IF(Datos!A11="","",IF(AT11="SI","Reponer ahora",IF(AND(AQ11<>"",AR11>0),"Bajar "&TEXT(AR11,"#,##0")&" un.","En rango")))
A12: =IF(Datos!A12="","",Datos!A12) | B12: =IF(Datos!A12="","",Datos!B12) | C12: =IF(Datos!A12="","",IFERROR(MAX(0,N(Datos!D12)),0)) | D12: =IF(Datos!A12="","",IFERROR(MAX(0,N(Datos!E12)),0)) | E12: =IF(Datos!A12="","",IFERROR(MAX(0,N(Datos!F12)),0)) | F12: =IF(Datos!A12="","",IFERROR(MAX(0,N(Datos!G12)),0)) | G12: =IF(Datos!A12="","",IFERROR(MAX(0,N(Datos!H12)),0)) | H12: =IF(Datos!A12="","",IFERROR(MAX(0,N(Datos!I12)),0)) | J12: =IF(Datos!A12="","",IF(MAX(C$2:C$301)-MIN(C$2:C$301)<0.000000001,0.5,(C12-MIN(C$2:C$301))/(MAX(C$2:C$301)-MIN(C$2:C$301)))+0.000000001) | K12: =IF(Datos!A12="","",IF(MAX(D$2:D$301)-MIN(D$2:D$301)<0.000000001,0.5,(D12-MIN(D$2:D$301))/(MAX(D$2:D$301)-MIN(D$2:D$301)))+0.000000001) | L12: =IF(Datos!A12="","",IF(MAX(E$2:E$301)-MIN(E$2:E$301)<0.000000001,0.5,(E12-MIN(E$2:E$301))/(MAX(E$2:E$301)-MIN(E$2:E$301)))+0.000000001) | M12: =IF(Datos!A12="","",IF(MAX(F$2:F$301)-MIN(F$2:F$301)<0.000000001,0.5,(F12-MIN(F$2:F$301))/(MAX(F$2:F$301)-MIN(F$2:F$301)))+0.000000001) | N12: =IF(Datos!A12="","",IF(MAX(G$2:G$301)-MIN(G$2:G$301)<0.000000001,0.5,(G12-MIN(G$2:G$301))/(MAX(G$2:G$301)-MIN(G$2:G$301)))+0.000000001) | O12: =IF(Datos!A12="","",IF(MAX(H$2:H$301)-MIN(H$2:H$301)<0.000000001,0.5,(H12-MIN(H$2:H$301))/(MAX(H$2:H$301)-MIN(H$2:H$301)))+0.000000001) | Q12: =IF(Datos!A12="","",(J12/SUM(J$2:J$301))*LN(J12/SUM(J$2:J$301))) | R12: =IF(Datos!A12="","",(K12/SUM(K$2:K$301))*LN(K12/SUM(K$2:K$301))) | S12: =IF(Datos!A12="","",(L12/SUM(L$2:L$301))*LN(L12/SUM(L$2:L$301))) | T12: =IF(Datos!A12="","",(M12/SUM(M$2:M$301))*LN(M12/SUM(M$2:M$301))) | U12: =IF(Datos!A12="","",(N12/SUM(N$2:N$301))*LN(N12/SUM(N$2:N$301))) | V12: =IF(Datos!A12="","",(O12/SUM(O$2:O$301))*LN(O12/SUM(O$2:O$301))) | X12: =IF(Datos!A12="","",IF(SUMSQ(C$2:C$301)=0,0,C12/SQRT(SUMSQ(C$2:C$301)))*$BE$2) | Y12: =IF(Datos!A12="","",IF(SUMSQ(D$2:D$301)=0,0,D12/SQRT(SUMSQ(D$2:D$301)))*$BE$3) | Z12: =IF(Datos!A12="","",IF(SUMSQ(E$2:E$301)=0,0,E12/SQRT(SUMSQ(E$2:E$301)))*$BE$4) | AA12: =IF(Datos!A12="","",IF(SUMSQ(F$2:F$301)=0,0,F12/SQRT(SUMSQ(F$2:F$301)))*$BE$5) | AB12: =IF(Datos!A12="","",IF(SUMSQ(G$2:G$301)=0,0,G12/SQRT(SUMSQ(G$2:G$301)))*$BE$6) | AC12: =IF(Datos!A12="","",IF(SUMSQ(H$2:H$301)=0,0,H12/SQRT(SUMSQ(H$2:H$301)))*$BE$7) | AE12: =IF(Datos!A12="","",SQRT(SUMXMY2(X12:AC12,$X$303:$AC$303))) | AF12: =IF(Datos!A12="","",SQRT(SUMXMY2(X12:AC12,$X$304:$AC$304))) | AG12: =IF(Datos!A12="","",IF(AE12+AF12<0.000000001,0.5,AF12/(AE12+AF12))) | AH12: =IF(Datos!A12="","",AG12*MAX(C12*D12,1)) | AI12: =IF(Datos!A12="","",SUMIF($AH$2:$AH$301,">="&AH12,$AH$2:$AH$301)/SUM($AH$2:$AH$301)) | AJ12: =IF(Datos!A12="","",IF(AI12<=Parametros!$B$13,"A",IF(AI12<=Parametros!$B$14,"B","C"))) | AK12: =IF(Datos!A12="","",VLOOKUP(AJ12,Parametros!$A$8:$C$10,2,FALSE)) | AL12: =IF(Datos!A12="","",VLOOKUP(AJ12,Parametros!$A$8:$C$10,3,FALSE)) | AM12: =IF(Datos!A12="","",NORMSINV(AK12)) | AN12: =IF(Datos!A12="","",D12/Parametros!$B$4) | AO12: =IF(Datos!A12="","",MAX(0,ROUNDUP(AM12*(AN12*Parametros!$B$3)*SQRT((AL12+E12)),0))) | AP12: =IF(Datos!A12="","",MAX(1,ROUNDUP(AN12*(AL12+E12)+AM12*(AN12*Parametros!$B$3)*SQRT((AL12+E12)),0))) | AQ12: =IF(Datos!A12="","",IF(Datos!J12="","",Datos!J12)) | AR12: =IF(OR(Datos!A12="",AQ12=""),"",MAX(0,AQ12-AP12)) | AS12: =IF(OR(Datos!A12="",AQ12=""),"",AR12*C12) | AT12: =IF(OR(Datos!A12="",AQ12=""),"",IF(AQ12<AO12,"SI","")) | AU12: =IF(Datos!A12="","",IF(AT12="SI","Reponer ahora",IF(AND(AQ12<>"",AR12>0),"Bajar "&TEXT(AR12,"#,##0")&" un.","En rango")))
A13: =IF(Datos!A13="","",Datos!A13) | B13: =IF(Datos!A13="","",Datos!B13) | C13: =IF(Datos!A13="","",IFERROR(MAX(0,N(Datos!D13)),0)) | D13: =IF(Datos!A13="","",IFERROR(MAX(0,N(Datos!E13)),0)) | E13: =IF(Datos!A13="","",IFERROR(MAX(0,N(Datos!F13)),0)) | F13: =IF(Datos!A13="","",IFERROR(MAX(0,N(Datos!G13)),0)) | G13: =IF(Datos!A13="","",IFERROR(MAX(0,N(Datos!H13)),0)) | H13: =IF(Datos!A13="","",IFERROR(MAX(0,N(Datos!I13)),0)) | J13: =IF(Datos!A13="","",IF(MAX(C$2:C$301)-MIN(C$2:C$301)<0.000000001,0.5,(C13-MIN(C$2:C$301))/(MAX(C$2:C$301)-MIN(C$2:C$301)))+0.000000001) | K13: =IF(Datos!A13="","",IF(MAX(D$2:D$301)-MIN(D$2:D$301)<0.000000001,0.5,(D13-MIN(D$2:D$301))/(MAX(D$2:D$301)-MIN(D$2:D$301)))+0.000000001) | L13: =IF(Datos!A13="","",IF(MAX(E$2:E$301)-MIN(E$2:E$301)<0.000000001,0.5,(E13-MIN(E$2:E$301))/(MAX(E$2:E$301)-MIN(E$2:E$301)))+0.000000001) | M13: =IF(Datos!A13="","",IF(MAX(F$2:F$301)-MIN(F$2:F$301)<0.000000001,0.5,(F13-MIN(F$2:F$301))/(MAX(F$2:F$301)-MIN(F$2:F$301)))+0.000000001) | N13: =IF(Datos!A13="","",IF(MAX(G$2:G$301)-MIN(G$2:G$301)<0.000000001,0.5,(G13-MIN(G$2:G$301))/(MAX(G$2:G$301)-MIN(G$2:G$301)))+0.000000001) | O13: =IF(Datos!A13="","",IF(MAX(H$2:H$301)-MIN(H$2:H$301)<0.000000001,0.5,(H13-MIN(H$2:H$301))/(MAX(H$2:H$301)-MIN(H$2:H$301)))+0.000000001) | Q13: =IF(Datos!A13="","",(J13/SUM(J$2:J$301))*LN(J13/SUM(J$2:J$301))) | R13: =IF(Datos!A13="","",(K13/SUM(K$2:K$301))*LN(K13/SUM(K$2:K$301))) | S13: =IF(Datos!A13="","",(L13/SUM(L$2:L$301))*LN(L13/SUM(L$2:L$301))) | T13: =IF(Datos!A13="","",(M13/SUM(M$2:M$301))*LN(M13/SUM(M$2:M$301))) | U13: =IF(Datos!A13="","",(N13/SUM(N$2:N$301))*LN(N13/SUM(N$2:N$301))) | V13: =IF(Datos!A13="","",(O13/SUM(O$2:O$301))*LN(O13/SUM(O$2:O$301))) | X13: =IF(Datos!A13="","",IF(SUMSQ(C$2:C$301)=0,0,C13/SQRT(SUMSQ(C$2:C$301)))*$BE$2) | Y13: =IF(Datos!A13="","",IF(SUMSQ(D$2:D$301)=0,0,D13/SQRT(SUMSQ(D$2:D$301)))*$BE$3) | Z13: =IF(Datos!A13="","",IF(SUMSQ(E$2:E$301)=0,0,E13/SQRT(SUMSQ(E$2:E$301)))*$BE$4) | AA13: =IF(Datos!A13="","",IF(SUMSQ(F$2:F$301)=0,0,F13/SQRT(SUMSQ(F$2:F$301)))*$BE$5) | AB13: =IF(Datos!A13="","",IF(SUMSQ(G$2:G$301)=0,0,G13/SQRT(SUMSQ(G$2:G$301)))*$BE$6) | AC13: =IF(Datos!A13="","",IF(SUMSQ(H$2:H$301)=0,0,H13/SQRT(SUMSQ(H$2:H$301)))*$BE$7) | AE13: =IF(Datos!A13="","",SQRT(SUMXMY2(X13:AC13,$X$303:$AC$303))) | AF13: =IF(Datos!A13="","",SQRT(SUMXMY2(X13:AC13,$X$304:$AC$304))) | AG13: =IF(Datos!A13="","",IF(AE13+AF13<0.000000001,0.5,AF13/(AE13+AF13))) | AH13: =IF(Datos!A13="","",AG13*MAX(C13*D13,1)) | AI13: =IF(Datos!A13="","",SUMIF($AH$2:$AH$301,">="&AH13,$AH$2:$AH$301)/SUM($AH$2:$AH$301)) | AJ13: =IF(Datos!A13="","",IF(AI13<=Parametros!$B$13,"A",IF(AI13<=Parametros!$B$14,"B","C"))) | AK13: =IF(Datos!A13="","",VLOOKUP(AJ13,Parametros!$A$8:$C$10,2,FALSE)) | AL13: =IF(Datos!A13="","",VLOOKUP(AJ13,Parametros!$A$8:$C$10,3,FALSE)) | AM13: =IF(Datos!A13="","",NORMSINV(AK13)) | AN13: =IF(Datos!A13="","",D13/Parametros!$B$4) | AO13: =IF(Datos!A13="","",MAX(0,ROUNDUP(AM13*(AN13*Parametros!$B$3)*SQRT((AL13+E13)),0))) | AP13: =IF(Datos!A13="","",MAX(1,ROUNDUP(AN13*(AL13+E13)+AM13*(AN13*Parametros!$B$3)*SQRT((AL13+E13)),0))) | AQ13: =IF(Datos!A13="","",IF(Datos!J13="","",Datos!J13)) | AR13: =IF(OR(Datos!A13="",AQ13=""),"",MAX(0,AQ13-AP13)) | AS13: =IF(OR(Datos!A13="",AQ13=""),"",AR13*C13) | AT13: =IF(OR(Datos!A13="",AQ13=""),"",IF(AQ13<AO13,"SI","")) | AU13: =IF(Datos!A13="","",IF(AT13="SI","Reponer ahora",IF(AND(AQ13<>"",AR13>0),"Bajar "&TEXT(AR13,"#,##0")&" un.","En rango")))
A14: =IF(Datos!A14="","",Datos!A14) | B14: =IF(Datos!A14="","",Datos!B14) | C14: =IF(Datos!A14="","",IFERROR(MAX(0,N(Datos!D14)),0)) | D14: =IF(Datos!A14="","",IFERROR(MAX(0,N(Datos!E14)),0)) | E14: =IF(Datos!A14="","",IFERROR(MAX(0,N(Datos!F14)),0)) | F14: =IF(Datos!A14="","",IFERROR(MAX(0,N(Datos!G14)),0)) | G14: =IF(Datos!A14="","",IFERROR(MAX(0,N(Datos!H14)),0)) | H14: =IF(Datos!A14="","",IFERROR(MAX(0,N(Datos!I14)),0)) | J14: =IF(Datos!A14="","",IF(MAX(C$2:C$301)-MIN(C$2:C$301)<0.000000001,0.5,(C14-MIN(C$2:C$301))/(MAX(C$2:C$301)-MIN(C$2:C$301)))+0.000000001) | K14: =IF(Datos!A14="","",IF(MAX(D$2:D$301)-MIN(D$2:D$301)<0.000000001,0.5,(D14-MIN(D$2:D$301))/(MAX(D$2:D$301)-MIN(D$2:D$301)))+0.000000001) | L14: =IF(Datos!A14="","",IF(MAX(E$2:E$301)-MIN(E$2:E$301)<0.000000001,0.5,(E14-MIN(E$2:E$301))/(MAX(E$2:E$301)-MIN(E$2:E$301)))+0.000000001) | M14: =IF(Datos!A14="","",IF(MAX(F$2:F$301)-MIN(F$2:F$301)<0.000000001,0.5,(F14-MIN(F$2:F$301))/(MAX(F$2:F$301)-MIN(F$2:F$301)))+0.000000001) | N14: =IF(Datos!A14="","",IF(MAX(G$2:G$301)-MIN(G$2:G$301)<0.000000001,0.5,(G14-MIN(G$2:G$301))/(MAX(G$2:G$301)-MIN(G$2:G$301)))+0.000000001) | O14: =IF(Datos!A14="","",IF(MAX(H$2:H$301)-MIN(H$2:H$301)<0.000000001,0.5,(H14-MIN(H$2:H$301))/(MAX(H$2:H$301)-MIN(H$2:H$301)))+0.000000001) | Q14: =IF(Datos!A14="","",(J14/SUM(J$2:J$301))*LN(J14/SUM(J$2:J$301))) | R14: =IF(Datos!A14="","",(K14/SUM(K$2:K$301))*LN(K14/SUM(K$2:K$301))) | S14: =IF(Datos!A14="","",(L14/SUM(L$2:L$301))*LN(L14/SUM(L$2:L$301))) | T14: =IF(Datos!A14="","",(M14/SUM(M$2:M$301))*LN(M14/SUM(M$2:M$301))) | U14: =IF(Datos!A14="","",(N14/SUM(N$2:N$301))*LN(N14/SUM(N$2:N$301))) | V14: =IF(Datos!A14="","",(O14/SUM(O$2:O$301))*LN(O14/SUM(O$2:O$301))) | X14: =IF(Datos!A14="","",IF(SUMSQ(C$2:C$301)=0,0,C14/SQRT(SUMSQ(C$2:C$301)))*$BE$2) | Y14: =IF(Datos!A14="","",IF(SUMSQ(D$2:D$301)=0,0,D14/SQRT(SUMSQ(D$2:D$301)))*$BE$3) | Z14: =IF(Datos!A14="","",IF(SUMSQ(E$2:E$301)=0,0,E14/SQRT(SUMSQ(E$2:E$301)))*$BE$4) | AA14: =IF(Datos!A14="","",IF(SUMSQ(F$2:F$301)=0,0,F14/SQRT(SUMSQ(F$2:F$301)))*$BE$5) | AB14: =IF(Datos!A14="","",IF(SUMSQ(G$2:G$301)=0,0,G14/SQRT(SUMSQ(G$2:G$301)))*$BE$6) | AC14: =IF(Datos!A14="","",IF(SUMSQ(H$2:H$301)=0,0,H14/SQRT(SUMSQ(H$2:H$301)))*$BE$7) | AE14: =IF(Datos!A14="","",SQRT(SUMXMY2(X14:AC14,$X$303:$AC$303))) | AF14: =IF(Datos!A14="","",SQRT(SUMXMY2(X14:AC14,$X$304:$AC$304))) | AG14: =IF(Datos!A14="","",IF(AE14+AF14<0.000000001,0.5,AF14/(AE14+AF14))) | AH14: =IF(Datos!A14="","",AG14*MAX(C14*D14,1)) | AI14: =IF(Datos!A14="","",SUMIF($AH$2:$AH$301,">="&AH14,$AH$2:$AH$301)/SUM($AH$2:$AH$301)) | AJ14: =IF(Datos!A14="","",IF(AI14<=Parametros!$B$13,"A",IF(AI14<=Parametros!$B$14,"B","C"))) | AK14: =IF(Datos!A14="","",VLOOKUP(AJ14,Parametros!$A$8:$C$10,2,FALSE)) | AL14: =IF(Datos!A14="","",VLOOKUP(AJ14,Parametros!$A$8:$C$10,3,FALSE)) | AM14: =IF(Datos!A14="","",NORMSINV(AK14)) | AN14: =IF(Datos!A14="","",D14/Parametros!$B$4) | AO14: =IF(Datos!A14="","",MAX(0,ROUNDUP(AM14*(AN14*Parametros!$B$3)*SQRT((AL14+E14)),0))) | AP14: =IF(Datos!A14="","",MAX(1,ROUNDUP(AN14*(AL14+E14)+AM14*(AN14*Parametros!$B$3)*SQRT((AL14+E14)),0))) | AQ14: =IF(Datos!A14="","",IF(Datos!J14="","",Datos!J14)) | AR14: =IF(OR(Datos!A14="",AQ14=""),"",MAX(0,AQ14-AP14)) | AS14: =IF(OR(Datos!A14="",AQ14=""),"",AR14*C14) | AT14: =IF(OR(Datos!A14="",AQ14=""),"",IF(AQ14<AO14,"SI","")) | AU14: =IF(Datos!A14="","",IF(AT14="SI","Reponer ahora",IF(AND(AQ14<>"",AR14>0),"Bajar "&TEXT(AR14,"#,##0")&" un.","En rango")))
A15: =IF(Datos!A15="","",Datos!A15) | B15: =IF(Datos!A15="","",Datos!B15) | C15: =IF(Datos!A15="","",IFERROR(MAX(0,N(Datos!D15)),0)) | D15: =IF(Datos!A15="","",IFERROR(MAX(0,N(Datos!E15)),0)) | E15: =IF(Datos!A15="","",IFERROR(MAX(0,N(Datos!F15)),0)) | F15: =IF(Datos!A15="","",IFERROR(MAX(0,N(Datos!G15)),0)) | G15: =IF(Datos!A15="","",IFERROR(MAX(0,N(Datos!H15)),0)) | H15: =IF(Datos!A15="","",IFERROR(MAX(0,N(Datos!I15)),0)) | J15: =IF(Datos!A15="","",IF(MAX(C$2:C$301)-MIN(C$2:C$301)<0.000000001,0.5,(C15-MIN(C$2:C$301))/(MAX(C$2:C$301)-MIN(C$2:C$301)))+0.000000001) | K15: =IF(Datos!A15="","",IF(MAX(D$2:D$301)-MIN(D$2:D$301)<0.000000001,0.5,(D15-MIN(D$2:D$301))/(MAX(D$2:D$301)-MIN(D$2:D$301)))+0.000000001) | L15: =IF(Datos!A15="","",IF(MAX(E$2:E$301)-MIN(E$2:E$301)<0.000000001,0.5,(E15-MIN(E$2:E$301))/(MAX(E$2:E$301)-MIN(E$2:E$301)))+0.000000001) | M15: =IF(Datos!A15="","",IF(MAX(F$2:F$301)-MIN(F$2:F$301)<0.000000001,0.5,(F15-MIN(F$2:F$301))/(MAX(F$2:F$301)-MIN(F$2:F$301)))+0.000000001) | N15: =IF(Datos!A15="","",IF(MAX(G$2:G$301)-MIN(G$2:G$301)<0.000000001,0.5,(G15-MIN(G$2:G$301))/(MAX(G$2:G$301)-MIN(G$2:G$301)))+0.000000001) | O15: =IF(Datos!A15="","",IF(MAX(H$2:H$301)-MIN(H$2:H$301)<0.000000001,0.5,(H15-MIN(H$2:H$301))/(MAX(H$2:H$301)-MIN(H$2:H$301)))+0.000000001) | Q15: =IF(Datos!A15="","",(J15/SUM(J$2:J$301))*LN(J15/SUM(J$2:J$301))) | R15: =IF(Datos!A15="","",(K15/SUM(K$2:K$301))*LN(K15/SUM(K$2:K$301))) | S15: =IF(Datos!A15="","",(L15/SUM(L$2:L$301))*LN(L15/SUM(L$2:L$301))) | T15: =IF(Datos!A15="","",(M15/SUM(M$2:M$301))*LN(M15/SUM(M$2:M$301))) | U15: =IF(Datos!A15="","",(N15/SUM(N$2:N$301))*LN(N15/SUM(N$2:N$301))) | V15: =IF(Datos!A15="","",(O15/SUM(O$2:O$301))*LN(O15/SUM(O$2:O$301))) | X15: =IF(Datos!A15="","",IF(SUMSQ(C$2:C$301)=0,0,C15/SQRT(SUMSQ(C$2:C$301)))*$BE$2) | Y15: =IF(Datos!A15="","",IF(SUMSQ(D$2:D$301)=0,0,D15/SQRT(SUMSQ(D$2:D$301)))*$BE$3) | Z15: =IF(Datos!A15="","",IF(SUMSQ(E$2:E$301)=0,0,E15/SQRT(SUMSQ(E$2:E$301)))*$BE$4) | AA15: =IF(Datos!A15="","",IF(SUMSQ(F$2:F$301)=0,0,F15/SQRT(SUMSQ(F$2:F$301)))*$BE$5) | AB15: =IF(Datos!A15="","",IF(SUMSQ(G$2:G$301)=0,0,G15/SQRT(SUMSQ(G$2:G$301)))*$BE$6) | AC15: =IF(Datos!A15="","",IF(SUMSQ(H$2:H$301)=0,0,H15/SQRT(SUMSQ(H$2:H$301)))*$BE$7) | AE15: =IF(Datos!A15="","",SQRT(SUMXMY2(X15:AC15,$X$303:$AC$303))) | AF15: =IF(Datos!A15="","",SQRT(SUMXMY2(X15:AC15,$X$304:$AC$304))) | AG15: =IF(Datos!A15="","",IF(AE15+AF15<0.000000001,0.5,AF15/(AE15+AF15))) | AH15: =IF(Datos!A15="","",AG15*MAX(C15*D15,1)) | AI15: =IF(Datos!A15="","",SUMIF($AH$2:$AH$301,">="&AH15,$AH$2:$AH$301)/SUM($AH$2:$AH$301)) | AJ15: =IF(Datos!A15="","",IF(AI15<=Parametros!$B$13,"A",IF(AI15<=Parametros!$B$14,"B","C"))) | AK15: =IF(Datos!A15="","",VLOOKUP(AJ15,Parametros!$A$8:$C$10,2,FALSE)) | AL15: =IF(Datos!A15="","",VLOOKUP(AJ15,Parametros!$A$8:$C$10,3,FALSE)) | AM15: =IF(Datos!A15="","",NORMSINV(AK15)) | AN15: =IF(Datos!A15="","",D15/Parametros!$B$4) | AO15: =IF(Datos!A15="","",MAX(0,ROUNDUP(AM15*(AN15*Parametros!$B$3)*SQRT((AL15+E15)),0))) | AP15: =IF(Datos!A15="","",MAX(1,ROUNDUP(AN15*(AL15+E15)+AM15*(AN15*Parametros!$B$3)*SQRT((AL15+E15)),0))) | AQ15: =IF(Datos!A15="","",IF(Datos!J15="","",Datos!J15)) | AR15: =IF(OR(Datos!A15="",AQ15=""),"",MAX(0,AQ15-AP15)) | AS15: =IF(OR(Datos!A15="",AQ15=""),"",AR15*C15) | AT15: =IF(OR(Datos!A15="",AQ15=""),"",IF(AQ15<AO15,"SI","")) | AU15: =IF(Datos!A15="","",IF(AT15="SI","Reponer ahora",IF(AND(AQ15<>"",AR15>0),"Bajar "&TEXT(AR15,"#,##0")&" un.","En rango")))
A16: =IF(Datos!A16="","",Datos!A16) | B16: =IF(Datos!A16="","",Datos!B16) | C16: =IF(Datos!A16="","",IFERROR(MAX(0,N(Datos!D16)),0)) | D16: =IF(Datos!A16="","",IFERROR(MAX(0,N(Datos!E16)),0)) | E16: =IF(Datos!A16="","",IFERROR(MAX(0,N(Datos!F16)),0)) | F16: =IF(Datos!A16="","",IFERROR(MAX(0,N(Datos!G16)),0)) | G16: =IF(Datos!A16="","",IFERROR(MAX(0,N(Datos!H16)),0)) | H16: =IF(Datos!A16="","",IFERROR(MAX(0,N(Datos!I16)),0)) | J16: =IF(Datos!A16="","",IF(MAX(C$2:C$301)-MIN(C$2:C$301)<0.000000001,0.5,(C16-MIN(C$2:C$301))/(MAX(C$2:C$301)-MIN(C$2:C$301)))+0.000000001) | K16: =IF(Datos!A16="","",IF(MAX(D$2:D$301)-MIN(D$2:D$301)<0.000000001,0.5,(D16-MIN(D$2:D$301))/(MAX(D$2:D$301)-MIN(D$2:D$301)))+0.000000001) | L16: =IF(Datos!A16="","",IF(MAX(E$2:E$301)-MIN(E$2:E$301)<0.000000001,0.5,(E16-MIN(E$2:E$301))/(MAX(E$2:E$301)-MIN(E$2:E$301)))+0.000000001) | M16: =IF(Datos!A16="","",IF(MAX(F$2:F$301)-MIN(F$2:F$301)<0.000000001,0.5,(F16-MIN(F$2:F$301))/(MAX(F$2:F$301)-MIN(F$2:F$301)))+0.000000001) | N16: =IF(Datos!A16="","",IF(MAX(G$2:G$301)-MIN(G$2:G$301)<0.000000001,0.5,(G16-MIN(G$2:G$301))/(MAX(G$2:G$301)-MIN(G$2:G$301)))+0.000000001) | O16: =IF(Datos!A16="","",IF(MAX(H$2:H$301)-MIN(H$2:H$301)<0.000000001,0.5,(H16-MIN(H$2:H$301))/(MAX(H$2:H$301)-MIN(H$2:H$301)))+0.000000001) | Q16: =IF(Datos!A16="","",(J16/SUM(J$2:J$301))*LN(J16/SUM(J$2:J$301))) | R16: =IF(Datos!A16="","",(K16/SUM(K$2:K$301))*LN(K16/SUM(K$2:K$301))) | S16: =IF(Datos!A16="","",(L16/SUM(L$2:L$301))*LN(L16/SUM(L$2:L$301))) | T16: =IF(Datos!A16="","",(M16/SUM(M$2:M$301))*LN(M16/SUM(M$2:M$301))) | U16: =IF(Datos!A16="","",(N16/SUM(N$2:N$301))*LN(N16/SUM(N$2:N$301))) | V16: =IF(Datos!A16="","",(O16/SUM(O$2:O$301))*LN(O16/SUM(O$2:O$301))) | X16: =IF(Datos!A16="","",IF(SUMSQ(C$2:C$301)=0,0,C16/SQRT(SUMSQ(C$2:C$301)))*$BE$2) | Y16: =IF(Datos!A16="","",IF(SUMSQ(D$2:D$301)=0,0,D16/SQRT(SUMSQ(D$2:D$301)))*$BE$3) | Z16: =IF(Datos!A16="","",IF(SUMSQ(E$2:E$301)=0,0,E16/SQRT(SUMSQ(E$2:E$301)))*$BE$4) | AA16: =IF(Datos!A16="","",IF(SUMSQ(F$2:F$301)=0,0,F16/SQRT(SUMSQ(F$2:F$301)))*$BE$5) | AB16: =IF(Datos!A16="","",IF(SUMSQ(G$2:G$301)=0,0,G16/SQRT(SUMSQ(G$2:G$301)))*$BE$6) | AC16: =IF(Datos!A16="","",IF(SUMSQ(H$2:H$301)=0,0,H16/SQRT(SUMSQ(H$2:H$301)))*$BE$7) | AE16: =IF(Datos!A16="","",SQRT(SUMXMY2(X16:AC16,$X$303:$AC$303))) | AF16: =IF(Datos!A16="","",SQRT(SUMXMY2(X16:AC16,$X$304:$AC$304))) | AG16: =IF(Datos!A16="","",IF(AE16+AF16<0.000000001,0.5,AF16/(AE16+AF16))) | AH16: =IF(Datos!A16="","",AG16*MAX(C16*D16,1)) | AI16: =IF(Datos!A16="","",SUMIF($AH$2:$AH$301,">="&AH16,$AH$2:$AH$301)/SUM($AH$2:$AH$301)) | AJ16: =IF(Datos!A16="","",IF(AI16<=Parametros!$B$13,"A",IF(AI16<=Parametros!$B$14,"B","C"))) | AK16: =IF(Datos!A16="","",VLOOKUP(AJ16,Parametros!$A$8:$C$10,2,FALSE)) | AL16: =IF(Datos!A16="","",VLOOKUP(AJ16,Parametros!$A$8:$C$10,3,FALSE)) | AM16: =IF(Datos!A16="","",NORMSINV(AK16)) | AN16: =IF(Datos!A16="","",D16/Parametros!$B$4) | AO16: =IF(Datos!A16="","",MAX(0,ROUNDUP(AM16*(AN16*Parametros!$B$3)*SQRT((AL16+E16)),0))) | AP16: =IF(Datos!A16="","",MAX(1,ROUNDUP(AN16*(AL16+E16)+AM16*(AN16*Parametros!$B$3)*SQRT((AL16+E16)),0))) | AQ16: =IF(Datos!A16="","",IF(Datos!J16="","",Datos!J16)) | AR16: =IF(OR(Datos!A16="",AQ16=""),"",MAX(0,AQ16-AP16)) | AS16: =IF(OR(Datos!A16="",AQ16=""),"",AR16*C16) | AT16: =IF(OR(Datos!A16="",AQ16=""),"",IF(AQ16<AO16,"SI","")) | AU16: =IF(Datos!A16="","",IF(AT16="SI","Reponer ahora",IF(AND(AQ16<>"",AR16>0),"Bajar "&TEXT(AR16,"#,##0")&" un.","En rango")))
